Workbook
Name million: 1000000
Name thousand: 1000

Sheet Check
B2: By Tab
B4: Consolidated | D4: =+#REF! -> #REF!
B5: Organic | D5: =+#REF! -> #REF!
B6: Food Systems | D6: =+#REF! -> #REF!
B7: Frulact Portugal | D7: =+#REF! -> #REF!
B8: Frulact France | D8: =+#REF! -> #REF!
B9: Frulact Germany | D9: =+#REF! -> #REF!
B10: Frulact Switzerland | D10: =+#REF! -> #REF!
B11: Frulact Maroc | D11: =+#REF! -> #REF!
B12: Frulact South Africa | D12: =+#REF! -> #REF!
B13: Frulact Canada | D13: =+#REF! -> #REF!
B14: Frulact USA | D14: =+#REF! -> #REF!
B15: Plant-Based | D15: =+#REF! -> #REF!
... B20: Add-ons | D20: =+#REF! -> #REF!
B21: Master Check | D21: =SUM(D4:D20) -> #REF!

Sheet Cover
K4: Strictly Private and Confidential

Sheet LBO Model >

Sheet LBO
B3: Sources & Uses | N3: IRR | O3: =+L43 -> 0.21128524
N4: MOIC | O4: =+M43 -> 2.5047266
B5: Sources | C5: €M | D5: xEBITDA | F5: Uses | G5: €M | H5: xEBITDA
B6: Equity ticket | C6: =+'Debt Summary'!D11 -> 296.4975 | D6: =+'Debt Summary'!E11 -> 5.7796784 | F6: =+'Debt Summary'!G11 -> Purchase Price | G6: =+'Debt Summary'!H11 -> 540 | H6: =+'Debt Summary'!I11 -> 10.526316
B7: TLA | C7: =+'Debt Summary'!D12 -> 0 | D7: =+'Debt Summary'!E12 -> 0
B8: TLB | C8: =+'Debt Summary'!D13 -> 256.5 | D8: =+'Debt Summary'!E13 -> 5 | F8: =+'Debt Summary'!G13 -> Structuring fees | G8: =+'Debt Summary'!H13 -> 4.8975 | H8: =+'Debt Summary'!I13 -> 0.095467836
B9: =+'Debt Summary'!C14 -> Holdco PIK | C9: =+'Debt Summary'!D14 -> 0 | D9: =+'Debt Summary'!E14 -> 0 | F9: =+'Debt Summary'!G14 -> Transaction cost | G9: =+'Debt Summary'!H14 -> 8.1 | H9: =+'Debt Summary'!I14 -> 0.15789474
B10: TOTAL | C10: =+ROUND(SUM(C6:C9),1) -> 553 | D10: =+SUM(D6:D9) -> 10.779678 | F10: TOTAL | G10: =+SUM(G6:G9) -> 552.9975 | H10: =+SUM(H6:H9) -> 10.779678
B11: Equity Cushion | C11: =+C6/C10 -> 0.53616184 | H11: =+ROUND(C10,0)=ROUND(G10,0) -> TRUE
B13: Returns
C15: Entry date | D15: 46022
C16: Exit date | D16: 47848
C17: Exit multiple | D17: 10
B20: Exit valuation analysis | J20: 46022 | K20: =+EOMONTH(J20,12) -> 46387 | L20: =+EOMONTH(K20,12) -> 46752 | M20: =+EOMONTH(L20,12) -> 47118 | N20: =+EOMONTH(M20,12) -> 47483 | O20: =+EOMONTH(N20,12) -> 47848 | P20: =+EOMONTH(O20,12) -> 48213
C22: EBITDA | J22: =+'Debt Summary'!M13 -> 51.3 | K22: =+'Debt Summary'!N13 -> 52.243319 | L22: =+'Debt Summary'!O13 -> 61.713285 | M22: =+'Debt Summary'!P13 -> 73.285082 | N22: =+'Debt Summary'!Q13 -> 79.587752 | O22: =+'Debt Summary'!R13 -> 87.783624 | P22: =+'Debt Summary'!S13 -> 89.539296
C23: EBITDA multiple | J23: =+D17 -> 10 | K23: =+J23 -> 10 | L23: =+K23 -> 10 | M23: =+L23 -> 10 | N23: =+M23 -> 10 | O23: =+N23 -> 10 | P23: =+O23 -> 10
C24: Enterprise Value | J24: =+J22*J23 -> 513 | K24: =+K22*K23 -> 522.43319 | L24: =+L22*L23 -> 617.13285 | M24: =+M22*M23 -> 732.85082 | N24: =+N22*N23 -> 795.87752 | O24: =+O22*O23 -> 877.83624 | P24: =+P22*P23 -> 895.39296
C25: Financial debt | J25: =-'Debt Summary'!M44 -> -256.5 | K25: =-'Debt Summary'!N44 -> -267.14142 | L25: =-'Debt Summary'!O44 -> -291.64354 | M25: =-'Debt Summary'!P44 -> -304.19406 | N25: =-'Debt Summary'!Q44 -> -304.19406 | O25: =-'Debt Summary'!R44 -> -304.19406 | P25: =-'Debt Summary'!S44 -> -304.19406
C26: Cash | J26: =+'Debt Summary'!M33 -> 0 | K26: =+'Debt Summary'!N33 -> 28.530578 | L26: =+'Debt Summary'!O33 -> 62.036428 | M26: =+'Debt Summary'!P33 -> 87.807268 | N26: =+'Debt Summary'!Q33 -> 10 | O26: =+'Debt Summary'!R33 -> 37.531609 | P26: =+'Debt Summary'!S33 -> 67.441735
C27: Transaction expenses | J27: =-J24*1.5% -> -7.695 | K27: =-K24*1.5% -> -7.8364979 | L27: =-L24*1.5% -> -9.2569928 | M27: =-M24*1.5% -> -10.992762 | N27: =-N24*1.5% -> -11.938163 | O27: =-O24*1.5% -> -13.167544 | P27: =-P24*1.5% -> -13.430894
C28: Equity Value | J28: =+SUM(J24:J27) -> 248.805 | K28: =+SUM(K24:K27) -> 275.98585 | L28: =+SUM(L24:L27) -> 378.26875 | M28: =+SUM(M24:M27) -> 505.47127 | N28: =+SUM(N24:N27) -> 489.74529 | O28: =+SUM(O24:O27) -> 598.00624 | P28: =+SUM(P24:P27) -> 645.20974
C30: Dividends received | J30: =+'Debt Summary'!M29 -> 0 | K30: =+'Debt Summary'!N29 -> 0 | L30: =+'Debt Summary'!O29 -> 0 | M30: =+'Debt Summary'!P29 -> 15.77084 | N30: =+'Debt Summary'!Q29 -> 111.33647 | O30: =+'Debt Summary'!R29 -> 17.531609 | P30: =+'Debt Summary'!S29 -> 19.910127
C32: IRR | J32: {=+TRANSPOSE(L38:L44)} -> 0 | K32: -0.069179836 | L32: 0.12950905 | M32: 0.20669718 | N32: 0.20239075 | O32: 0.21128524 | P32: 0.19702684
C33: MOIC | J33: {=+TRANSPOSE(M38:M44)} -> 0.83914704 | K33: 0.93082016 | L33: 1.2757907 | M33: 1.7579983 | N33: 2.0804648 | O33: 2.5047266 | P33: 2.7310813
D36: Funding
D37: =+C38 -> 46022 | E37: =+D37 -> 46022 | F37: =+EOMONTH(E37,12) -> 46387 | G37: =+EOMONTH(F37,12) -> 46752 | H37: =+EOMONTH(G37,12) -> 47118 | I37: =+EOMONTH(H37,12) -> 47483 | J37: =+EOMONTH(I37,12) -> 47848 | K37: =+EOMONTH(J37,12) -> 48213 | L37: IRR | M37: MOIC
C38: =+D15 -> 46022 | D38: =-C6 -> -296.4975 | E38: =+IF($C38=J$20,J$28,0)+IF($C38>=J$20,J$30,0) -> 248.805 | F38: =+IF($C38=K$20,K$28,0)+IF($C38>=K$20,K$30,0) -> 0 | G38: =+IF($C38=L$20,L$28,0)+IF($C38>=L$20,L$30,0) -> 0 | H38: =+IF($C38=M$20,M$28,0)+IF($C38>=M$20,M$30,0) -> 0 | I38: =+IF($C38=N$20,N$28,0)+IF($C38>=N$20,N$30,0) -> 0 | J38: =+IF($C38=O$20,O$28,0)+IF($C38>=O$20,O$30,0) -> 0 | K38: =+IF($C38=P$20,P$28,0)+IF($C38>=P$20,P$30,0) -> 0 | L38: =IFERROR(+XIRR($D38:$K38,$D$37:$K$37),0) -> 0 | M38: =IFERROR(+SUM(E38:K38)/-D38,0) -> 0.83914704
C39: =+EOMONTH(C38,12) -> 46387 | D39: =+D38 -> -296.4975 | E39: =+IF($C39=J$20,J$28,0)+IF($C39>=J$20,J$30,0) -> 0 | F39: =+IF($C39=K$20,K$28,0)+IF($C39>=K$20,K$30,0) -> 275.98585 | G39: =+IF($C39=L$20,L$28,0)+IF($C39>=L$20,L$30,0) -> 0 | H39: =+IF($C39=M$20,M$28,0)+IF($C39>=M$20,M$30,0) -> 0 | I39: =+IF($C39=N$20,N$28,0)+IF($C39>=N$20,N$30,0) -> 0 | J39: =+IF($C39=O$20,O$28,0)+IF($C39>=O$20,O$30,0) -> 0 | K39: =+IF($C39=P$20,P$28,0)+IF($C39>=P$20,P$30,0) -> 0 | L39: =IFERROR(+XIRR($D39:$K39,$D$37:$K$37),0) -> -0.069179836 | M39: =IFERROR(+SUM(E39:K39)/-D39,0) -> 0.93082016
C40: =+EOMONTH(C39,12) -> 46752 | D40: =+D39 -> -296.4975 | E40: =+IF($C40=J$20,J$28,0)+IF($C40>=J$20,J$30,0) -> 0 | F40: =+IF($C40=K$20,K$28,0)+IF($C40>=K$20,K$30,0) -> 0 | G40: =+IF($C40=L$20,L$28,0)+IF($C40>=L$20,L$30,0) -> 378.26875 | H40: =+IF($C40=M$20,M$28,0)+IF($C40>=M$20,M$30,0) -> 0 | I40: =+IF($C40=N$20,N$28,0)+IF($C40>=N$20,N$30,0) -> 0 | J40: =+IF($C40=O$20,O$28,0)+IF($C40>=O$20,O$30,0) -> 0 | K40: =+IF($C40=P$20,P$28,0)+IF($C40>=P$20,P$30,0) -> 0 | L40: =IFERROR(+XIRR($D40:$K40,$D$37:$K$37),0) -> 0.12950905 | M40: =IFERROR(+SUM(E40:K40)/-D40,0) -> 1.2757907
C41: =+EOMONTH(C40,12) -> 47118 | D41: =+D40 -> -296.4975 | E41: =+IF($C41=J$20,J$28,0)+IF($C41>=J$20,J$30,0) -> 0 | F41: =+IF($C41=K$20,K$28,0)+IF($C41>=K$20,K$30,0) -> 0 | G41: =+IF($C41=L$20,L$28,0)+IF($C41>=L$20,L$30,0) -> 0 | H41: =+IF($C41=M$20,M$28,0)+IF($C41>=M$20,M$30,0) -> 521.24211 | I41: =+IF($C41=N$20,N$28,0)+IF($C41>=N$20,N$30,0) -> 0 | J41: =+IF($C41=O$20,O$28,0)+IF($C41>=O$20,O$30,0) -> 0 | K41: =+IF($C41=P$20,P$28,0)+IF($C41>=P$20,P$30,0) -> 0 | L41: =IFERROR(+XIRR($D41:$K41,$D$37:$K$37),0) -> 0.20669718 | M41: =IFERROR(+SUM(E41:K41)/-D41,0) -> 1.7579983
C42: =+EOMONTH(C41,12) -> 47483 | D42: =+D41 -> -296.4975 | E42: =+IF($C42=J$20,J$28,0)+IF($C42>=J$20,J$30,0) -> 0 | F42: =+IF($C42=K$20,K$28,0)+IF($C42>=K$20,K$30,0) -> 0 | G42: =+IF($C42=L$20,L$28,0)+IF($C42>=L$20,L$30,0) -> 0 | H42: =+IF($C42=M$20,M$28,0)+IF($C42>=M$20,M$30,0) -> 15.77084 | I42: =+IF($C42=N$20,N$28,0)+IF($C42>=N$20,N$30,0) -> 601.08176 | J42: =+IF($C42=O$20,O$28,0)+IF($C42>=O$20,O$30,0) -> 0 | K42: =+IF($C42=P$20,P$28,0)+IF($C42>=P$20,P$30,0) -> 0 | L42: =IFERROR(+XIRR($D42:$K42,$D$37:$K$37),0) -> 0.20239075 | M42: =IFERROR(+SUM(E42:K42)/-D42,0) -> 2.0804648
C43: =+EOMONTH(C42,12) -> 47848 | D43: =+D42 -> -296.4975 | E43: =+IF($C43=J$20,J$28,0)+IF($C43>=J$20,J$30,0) -> 0 | F43: =+IF($C43=K$20,K$28,0)+IF($C43>=K$20,K$30,0) -> 0 | G43: =+IF($C43=L$20,L$28,0)+IF($C43>=L$20,L$30,0) -> 0 | H43: =+IF($C43=M$20,M$28,0)+IF($C43>=M$20,M$30,0) -> 15.77084 | I43: =+IF($C43=N$20,N$28,0)+IF($C43>=N$20,N$30,0) -> 111.33647 | J43: =+IF($C43=O$20,O$28,0)+IF($C43>=O$20,O$30,0) -> 615.53785 | K43: =+IF($C43=P$20,P$28,0)+IF($C43>=P$20,P$30,0) -> 0 | L43: =IFERROR(+XIRR($D43:$K43,$D$37:$K$37),0) -> 0.21128524 | M43: =IFERROR(+SUM(E43:K43)/-D43,0) -> 2.5047266
C44: =+EOMONTH(C43,12) -> 48213 | D44: =+D43 -> -296.4975 | E44: =+IF($C44=J$20,J$28,0)+IF($C44>=J$20,J$30,0) -> 0 | F44: =+IF($C44=K$20,K$28,0)+IF($C44>=K$20,K$30,0) -> 0 | G44: =+IF($C44=L$20,L$28,0)+IF($C44>=L$20,L$30,0) -> 0 | H44: =+IF($C44=M$20,M$28,0)+IF($C44>=M$20,M$30,0) -> 15.77084 | I44: =+IF($C44=N$20,N$28,0)+IF($C44>=N$20,N$30,0) -> 111.33647 | J44: =+IF($C44=O$20,O$28,0)+IF($C44>=O$20,O$30,0) -> 17.531609 | K44: =+IF($C44=P$20,P$28,0)+IF($C44>=P$20,P$30,0) -> 665.11987 | L44: =IFERROR(+XIRR($D44:$K44,$D$37:$K$37),0) -> 0.19702684 | M44: =IFERROR(+SUM(E44:K44)/-D44,0) -> 2.7310813

Sheet Debt Summary
C2: =RIGHT(CELL("filename",D1), LEN(CELL("filename", D1))- FIND("]", CELL("filename", D1), 1)) -> Debt Summary
C4: Key output | K4: Revenues & Cashflow Statement
M5: FY25B | N5: FY26F | O5: FY27F | P5: FY28F | Q5: FY29F | R5: FY30F | S5: FY31F | T5: FY32F | U5: 25B-32F | V5: 26B-32F CAGR
C6: Estimated closing | D6: =Model!D4 -> 46022
K7: Revenue | M7: ='Active Case'!F9 -> 267.66926 | N7: ='Active Case'!G9 -> 300.63698 | O7: ='Active Case'!H9 -> 344.37965 | P7: ='Active Case'!I9 -> 386.42074 | Q7: ='Active Case'!J9 -> 411.17115 | R7: ='Active Case'!K9 -> 438.6581 | S7: ='Active Case'!L9 -> 447.43126 | T7: ='Active Case'!M9 -> 456.37989 | U7: =+SUM(M7:T7) -> 3052.747 | V7: =+(T7/M7)^(1/7)-1 -> 0.079205128
C8: Sources & Uses | K8: Revenue growth YoY | N8: =+N7/M7-1 -> 0.1231659 | O8: =+O7/N7-1 -> 0.14549995 | P8: =+P7/O7-1 -> 0.12207776 | Q8: =+Q7/P7-1 -> 0.064050414 | R8: =+R7/Q7-1 -> 0.066850379 | S8: =+S7/R7-1 -> 0.02 | T8: =+T7/S7-1 -> 0.02
K9: EBITDA | M9: ='Active Case'!F12 -> 45.111661 | N9: ='Active Case'!G12 -> 52.243319 | O9: ='Active Case'!H12 -> 61.713285 | P9: ='Active Case'!I12 -> 73.285082 | Q9: ='Active Case'!J12 -> 79.587752 | R9: ='Active Case'!K12 -> 87.783624 | S9: ='Active Case'!L12 -> 89.539296 | T9: ='Active Case'!M12 -> 91.330082 | U9: =+SUM(M9:T9) -> 580.5941 | V9: =+(T9/M9)^(1/7)-1 -> 0.10601424
C10: Sources | D10: €M | E10: xEBITDA | G10: Uses | H10: €M | I10: xEBITDA | K10: EBITDA margin | M10: =+M9/M7 -> 0.16853508 | N10: =+N9/N7 -> 0.17377543 | O10: =+O9/O7 -> 0.17920132 | P10: =+P9/P7 -> 0.18965101 | Q10: =+Q9/Q7 -> 0.19356356 | R10: =+R9/R7 -> 0.20011855 | S10: =+S9/S7 -> 0.20011855 | T10: =+T9/T7 -> 0.20011855
C11: Equity ticket | D11: =+'Debt Structure'!D51 -> 296.4975 | E11: =+D11/$M$13 -> 5.7796784 | G11: =+'Debt Structure'!F51 -> Purchase Price | H11: =+'Debt Structure'!G51 -> 540 | I11: =+H11/$M$13 -> 10.526316
C12: TLA | D12: =+'Debt Structure'!D52 -> 0 | E12: =+D12/$M$13 -> 0 | K12: Adjustments & normalizations | M12: =+'Active Case'!F16 -> 6.1883392 | N12: =+'Active Case'!G16 -> 0 | O12: =+'Active Case'!H16 -> 0 | P12: =+'Active Case'!I16 -> 0 | Q12: =+'Active Case'!J16 -> 0 | R12: =+'Active Case'!K16 -> 0 | S12: =+'Active Case'!L16 -> 0 | T12: =+'Active Case'!M16 -> 0
C13: TLB | D13: =+'Debt Structure'!D53 -> 256.5 | E13: =+D13/$M$13 -> 5 | G13: =+'Debt Structure'!F52 -> Structuring fees | H13: =+'Debt Structure'!G52 -> 4.8975 | I13: =+H13/$M$13 -> 0.095467836 | K13: Adj. normalized EBITDA | M13: =+'Active Case'!F17 -> 51.3 | N13: =+'Active Case'!G17 -> 52.243319 | O13: =+'Active Case'!H17 -> 61.713285 | P13: =+'Active Case'!I17 -> 73.285082 | Q13: =+'Active Case'!J17 -> 79.587752 | R13: =+'Active Case'!K17 -> 87.783624 | S13: =+'Active Case'!L17 -> 89.539296 | T13: =+'Active Case'!M17 -> 91.330082 | U13: =+SUM(M13:T13) -> 586.78244 | V13: =+(T13/M13)^(1/7)-1 -> 0.085888446
C14: =+'Debt Structure'!C54 -> Holdco PIK | D14: =+'Debt Structure'!D54 -> 0 | E14: =+D14/$M$13 -> 0 | G14: =+'Debt Structure'!F54 -> Transaction cost | H14: =+'Debt Structure'!G54 -> 8.1 | I14: =+H14/$M$13 -> 0.15789474 | K14: EBITDA margin | M14: =+M13/M7 -> 0.19165443 | N14: =+N13/N7 -> 0.17377543 | O14: =+O13/O7 -> 0.17920132 | P14: =+P13/P7 -> 0.18965101 | Q14: =+Q13/Q7 -> 0.19356356 | R14: =+R13/R7 -> 0.20011855 | S14: =+S13/S7 -> 0.20011855 | T14: =+T13/T7 -> 0.20011855
C15: TOTAL | D15: =+ROUND(SUM(D11:D14),1) -> 553 | E15: =+SUM(E11:E14) -> 10.779678 | G15: TOTAL | H15: =+SUM(H11:H14) -> 552.9975 | I15: =+SUM(I11:I14) -> 10.779678 | K15: Change in Working Capital | M15: ='Active Case'!F30 -> -5.8299854 | N15: ='Active Case'!G30 -> -5.0017419 | O15: ='Active Case'!H30 -> -6.8476121 | P15: ='Active Case'!I30 -> -6.1780846 | Q15: ='Active Case'!J30 -> -2.5470106 | R15: ='Active Case'!K30 -> -2.9852206 | S15: ='Active Case'!L30 -> -1.5660094 | T15: ='Active Case'!M30 -> -1.5973296 | U15: =+SUM(M15:T15) -> -32.552994 | V15: =+(T15/M15)^(1/7)-1 -> -0.16885787
C16: Equity Cushion | D16: =+D11/D15 -> 0.53616184 | I16: =+ROUND(D15,0)=ROUND(H15,0) -> TRUE | K16: Total Capex | M16: ='Active Case'!F33+'Active Case'!F36 -> -13.806 | N16: ='Active Case'!G33+'Active Case'!G36 -> -10.641421 | O16: ='Active Case'!H33+'Active Case'!H36 -> -24.502119 | P16: ='Active Case'!I33+'Active Case'!I36 -> -12.550525 | Q16: ='Active Case'!J33+'Active Case'!J36 -> -16.469825 | R16: ='Active Case'!K33+'Active Case'!K36 -> -11.001133 | S16: ='Active Case'!L33+'Active Case'!L36 -> -8.773162 | T16: ='Active Case'!M33+'Active Case'!M36 -> -8.773162 | U16: =+SUM(M16:T16) -> -106.51735 | V16: =+(T16/M16)^(1/7)-1 -> -0.062719128
K17: Taxes paid | M17: ='Active Case'!F23 -> -8.2650988 | N17: ='Active Case'!G23 -> -3.7039729 | O17: ='Active Case'!H23 -> -5.6672515 | P17: ='Active Case'!I23 -> -9.1167539 | Q17: ='Active Case'!J23 -> -10.349509 | R17: ='Active Case'!K23 -> -12.041849 | S17: ='Active Case'!L23 -> -12.687668 | T17: ='Active Case'!M23 -> -14.216824 | U17: =+SUM(M17:T17) -> -76.048928 | V17: =+(T17/M17)^(1/7)-1 -> 0.080564384
C18: Capital Structure - Frulact | K18: Operating Free Cash Flow | M18: =+M9+SUM(M15:M17) -> 17.210577 | N18: =+N9+SUM(N15:N17) -> 32.896183 | O18: =+O9+SUM(O15:O17) -> 24.696303 | P18: =+P9+SUM(P15:P17) -> 45.439719 | Q18: =+Q9+SUM(Q15:Q17) -> 50.221407 | R18: =+R9+SUM(R15:R17) -> 61.755421 | S18: =+S9+SUM(S15:S17) -> 66.512457 | T18: =+T9+SUM(T15:T17) -> 66.742767 | U18: =+SUM(M18:T18) -> 365.47483 | V18: =+(T18/M18)^(1/7)-1 -> 0.21363186
K19: % Operating FCF Margin | M19: =IF(+M18/M9<0,"n.m.",M18/M9) -> 0.3815106 | N19: =IF(+N18/N9<0,"n.m.",N18/N9) -> 0.62967254 | O19: =IF(+O18/O9<0,"n.m.",O18/O9) -> 0.40017806 | P19: =IF(+P18/P9<0,"n.m.",P18/P9) -> 0.6200405 | Q19: =IF(+Q18/Q9<0,"n.m.",Q18/Q9) -> 0.63101929 | R19: =IF(+R18/R9<0,"n.m.",R18/R9) -> 0.70349591 | S19: =IF(+S18/S9<0,"n.m.",S18/S9) -> 0.74282979 | T19: =IF(+T18/T9<0,"n.m.",T18/T9) -> 0.73078623
C20: Capital Structure | D20: EURm | E20: xEBITDA | K20: Cash flow available for debt service | M20: =M18 -> 17.210577 | N20: =N18 -> 32.896183 | O20: =O18 -> 24.696303 | P20: =P18 -> 45.439719 | Q20: =Q18 -> 50.221407 | R20: =R18 -> 61.755421 | S20: =S18 -> 66.512457 | T20: =T18 -> 66.742767 | U20: =+SUM(M20:T20) -> 365.47483 | V20: =+(T20/M20)^(1/7)-1 -> 0.21363186
C21: ='Debt Structure'!C22 -> TLA | D21: =+D12 -> 0 | E21: =+D21/$M$13 -> 0 | K21: Debt Service | M21: =+SUM(M22:M25) -> 0 | N21: =+SUM(N22:N25) -> -15.007027 | O21: =+SUM(O22:O25) -> -15.692572 | P21: =+SUM(P22:P25) -> -16.448564 | Q21: =+SUM(Q22:Q25) -> -16.692203 | R21: =+SUM(R22:R25) -> -16.692203 | S21: =+SUM(S22:S25) -> -16.692203 | T21: =+SUM(T22:T25) -> -318.82474
C22: ='Debt Structure'!C23 -> TLB | D22: =+D13 -> 256.5 | E22: =+D22/$M$13 -> 5 | K22: =Model!C81 -> TLA | M22: =Model!L81+Model!L87 -> 0 | N22: =Model!Q81+Model!Q87 -> 0 | O22: =Model!V81+Model!V87 -> 0 | P22: =Model!AA81+Model!AA87 -> 0 | Q22: =Model!AF81+Model!AF87 -> 0 | R22: =Model!AK81+Model!AK87 -> 0 | S22: =Model!AP81+Model!AP87 -> 0 | T22: =Model!AU81+Model!AU87 -> 0
C23: ='Debt Structure'!C24 -> Acquisition debt | D23: =+SUM(D21:D22) -> 256.5 | E23: ='Debt Structure'!E24 -> 5 | K23: =Model!C82 -> TLB | M23: =Model!L82+Model!L88 -> 0 | N23: =Model!Q82+Model!Q88 -> -14.1075 | O23: =Model!V82+Model!V88 -> -14.1075 | P23: =Model!AA82+Model!AA88 -> -14.1075 | Q23: =Model!AF82+Model!AF88 -> -14.1075 | R23: =Model!AK82+Model!AK88 -> -14.1075 | S23: =Model!AP82+Model!AP88 -> -14.1075 | T23: =Model!AU82+Model!AU88 -> -268.84406
K24: =Model!C83 -> CAF | M24: =Model!L83+Model!L89 -> 0 | N24: =Model!Q83+Model!Q89 -> -0.69952664 | O24: =Model!V83+Model!V89 -> -1.3850716 | P24: =Model!AA83+Model!AA89 -> -2.1410639 | Q24: =Model!AF83+Model!AF89 -> -2.3847032 | R24: =Model!AK83+Model!AK89 -> -2.3847032 | S24: =Model!AP83+Model!AP89 -> -2.3847032 | T24: =Model!AU83+Model!AU89 -> -49.78068
C25: ='Debt Structure'!C29 -> PIK | D25: =+D14 -> 0 | E25: =+D25/$M$13 -> 0 | K25: =Model!C84 -> RCF | M25: =Model!L84+Model!L90 -> 0 | N25: =Model!Q84+Model!Q90 -> -0.2 | O25: =Model!V84+Model!V90 -> -0.2 | P25: =Model!AA84+Model!AA90 -> -0.2 | Q25: =Model!AF84+Model!AF90 -> -0.2 | R25: =Model!AK84+Model!AK90 -> -0.2 | S25: =Model!AP84+Model!AP90 -> -0.2 | T25: =Model!AU84+Model!AU90 -> -0.2
C26: ='Debt Structure'!C30 -> Total Net Debt | D26: =+D25+D23 -> 256.5 | E26: ='Debt Structure'!E30 -> 5 | K26: Debt drawdown | M26: =Model!L92*0 -> 0 | N26: =Model!Q92 -> 10.641421 | O26: =Model!V92 -> 24.502119 | P26: =Model!AA92 -> 12.550525 | Q26: =Model!AF92 -> 0 | R26: =Model!AK92 -> 0 | S26: =+Model!AP92 -> 0 | T26: =+Model!AU92 -> 0 | U26: =+SUM(M26:T26) -> 47.694064
K27: Free Cash Flow | M27: =+M20+M21+M26 -> 17.210577 | N27: =+N20+N21+N26 -> 28.530578 | O27: =+O20+O21+O26 -> 33.50585 | P27: =+P20+P21+P26 -> 41.54168 | Q27: =+Q20+Q21+Q26 -> 33.529203 | R27: =+R20+R21+R26 -> 45.063218 | S27: =+S20+S21+S26 -> 49.820253 | T27: =+T20+T21+T26 -> -252.08198 | U27: =+SUM(M27:T27) -> -2.8806164
C28: ='Debt Structure'!C26 -> Cash | D28: ='Debt Structure'!D26 -> 0 | E28: =+D28/$M$13 -> 0 | K28: % Operating FCF Margin | M28: =+M27/M9 -> 0.3815106 | N28: =+N27/N9 -> 0.54610959 | O28: =+O27/O9 -> 0.54292767 | P28: =+P27/P9 -> 0.56685042 | Q28: =+Q27/Q9 -> 0.42128597 | R28: =+R27/R9 -> 0.51334424 | S28: =+S27/S9 -> 0.55640658 | T28: =+T27/T9 -> -2.7601199
C29: ='Debt Structure'!C27 -> Total Net Debt | D29: ='Debt Structure'!D27 -> 256.5 | E29: ='Debt Structure'!E27 -> 5 | K29: Dividends to JDM | N29: =+'Active Case'!G65 -> 0 | O29: =+'Active Case'!H65 -> 0 | P29: =+'Active Case'!I65 -> 15.77084 | Q29: =+'Active Case'!J65 -> 111.33647 | R29: =+'Active Case'!K65 -> 17.531609 | S29: =+'Active Case'!L65 -> 19.910127 | T29: =+'Active Case'!M65 -> 0
C31: ='Debt Structure'!C32 -> RCF | D31: ='Debt Structure'!D32 -> 20 | E31: =+D31/$M$13 -> 0.38986355
C32: ='Debt Structure'!C33 -> CAF | D32: ='Debt Structure'!D33 -> 50 | E32: =+D32/$M$13 -> 0.97465887 | K32: Cash BoP | N32: =+M33 -> 0 | O32: =+N33 -> 28.530578 | P32: =+O33 -> 62.036428 | Q32: =+P33 -> 87.807268 | R32: =+Q33 -> 10 | S32: =+R33 -> 37.531609 | T32: =+S33 -> 67.441735
C33: ='Debt Structure'!C34 -> Total | D33: ='Debt Structure'!D34 -> 326.5 | E33: ='Debt Structure'!E34 -> 6.3645224 | K33: Cash EoP | M33: ='Debt Structure'!D26 -> 0 | N33: =+N27+N32-N29 -> 28.530578 | O33: =+O27+O32-O29 -> 62.036428 | P33: =+P27+P32-P29 -> 87.807268 | Q33: =+Q27+Q32-Q29 -> 10 | R33: =+R27+R32-R29 -> 37.531609 | S33: =+S27+S32-S29 -> 67.441735 | T33: =+T27+T32-T29 -> -184.64024
K34: Check | M34: =ROUND(+Model!L102,1)=ROUND(M33,1) -> TRUE | N34: =ROUND(+Model!Q102,1)=ROUND(N33,1) -> TRUE | O34: =ROUND(+Model!V102,1)=ROUND(O33,1) -> TRUE | P34: =ROUND(+Model!AA102,1)=ROUND(P33,1) -> TRUE | Q34: =ROUND(+Model!AF102,1)=ROUND(Q33,1) -> TRUE | R34: =ROUND(+Model!AK102,1)=ROUND(R33,1) -> TRUE | S34: =ROUND(+Model!AP102,1)=ROUND(S33,1) -> TRUE | T34: =ROUND(+Model!AU102,1)=ROUND(T33,1) -> TRUE
C36: Covenants (Semi-annual) | K36: Net Debt BS Items
M37: FY25B | N37: FY26F | O37: FY27F | P37: FY28F | Q37: FY29F | R37: FY30F | S37: FY31F | T37: FY32F
C38: Dates | D38: Leverage | E38: Covenant | F38: CHECK
C39: {=+TRANSPOSE(Model!L10:AM10)} -> 46112 | D39: =IF(SUMIF(Model!$H$10:$AM$10,C39,Model!$H$12:$AM$12)=0,"n.a.",SUMIF(Model!$H$10:$AM$10,C39,Model!$H$12:$AM$12)) -> 4.8895653 | E39: =IF(SUMIF(Model!$H$10:$AM$10,C39,Model!$H$16:$AM$16)=0,"n.a.",SUMIF(Model!$H$10:$AM$10,C39,Model!$H$16:$AM$16)) -> 8.15 | F39: =+N(E39>D39) -> 1 | K39: Cash EoP | N39: =N33 -> 28.530578 | O39: =O33 -> 62.036428 | P39: =P33 -> 87.807268 | Q39: =Q33 -> 10 | R39: =R33 -> 37.531609 | S39: =S33 -> 67.441735 | T39: =T33 -> -184.64024
C40: 46203 | D40: =IF(SUMIF(Model!$H$10:$AM$10,C40,Model!$H$12:$AM$12)=0,"n.a.",SUMIF(Model!$H$10:$AM$10,C40,Model!$H$12:$AM$12)) -> 4.7806506 | E40: =IF(SUMIF(Model!$H$10:$AM$10,C40,Model!$H$16:$AM$16)=0,"n.a.",SUMIF(Model!$H$10:$AM$10,C40,Model!$H$16:$AM$16)) -> 8 | F40: =+N(E40>D40) -> 1
C41: 46295 | D41: =IF(SUMIF(Model!$H$10:$AM$10,C41,Model!$H$12:$AM$12)=0,"n.a.",SUMIF(Model!$H$10:$AM$10,C41,Model!$H$12:$AM$12)) -> 4.6732351 | E41: =IF(SUMIF(Model!$H$10:$AM$10,C41,Model!$H$16:$AM$16)=0,"n.a.",SUMIF(Model!$H$10:$AM$10,C41,Model!$H$16:$AM$16)) -> 7.8 | F41: =+N(E41>D41) -> 1 | K41: Debt BoP | N41: =+M44 -> 256.5 | O41: =+N44 -> 267.14142 | P41: =+O44 -> 291.64354 | Q41: =+P44 -> 304.19406 | R41: =+Q44 -> 304.19406 | S41: =+R44 -> 304.19406 | T41: =+S44 -> 304.19406
C42: 46387 | D42: =IF(SUMIF(Model!$H$10:$AM$10,C42,Model!$H$12:$AM$12)=0,"n.a.",SUMIF(Model!$H$10:$AM$10,C42,Model!$H$12:$AM$12)) -> 4.5672987 | E42: =IF(SUMIF(Model!$H$10:$AM$10,C42,Model!$H$16:$AM$16)=0,"n.a.",SUMIF(Model!$H$10:$AM$10,C42,Model!$H$16:$AM$16)) -> 7.65 | F42: =+N(E42>D42) -> 1 | K42: Drawdown debt | N42: =Model!Q92 -> 10.641421 | O42: =Model!V92 -> 24.502119 | P42: =Model!AA92 -> 12.550525 | Q42: =Model!AF92 -> 0 | R42: =Model!AK92 -> 0 | S42: =Model!AP92 -> 0 | T42: =Model!AU92 -> 0
C43: 46477 | D43: =IF(SUMIF(Model!$H$10:$AM$10,C43,Model!$H$12:$AM$12)=0,"n.a.",SUMIF(Model!$H$10:$AM$10,C43,Model!$H$12:$AM$12)) -> 4.3263966 | E43: =IF(SUMIF(Model!$H$10:$AM$10,C43,Model!$H$16:$AM$16)=0,"n.a.",SUMIF(Model!$H$10:$AM$10,C43,Model!$H$16:$AM$16)) -> 7.25 | F43: =+N(E43>D43) -> 1 | K43: Amortizations | N43: =Model!Q86 -> 0 | O43: =Model!V86 -> 0 | P43: =Model!AA86 -> 0 | Q43: =Model!AF86 -> 0 | R43: =Model!AK86 -> 0 | S43: =Model!AP86 -> 0 | T43: =Model!AU86 -> -304.19406
C44: 46568 | D44: =IF(SUMIF(Model!$H$10:$AM$10,C44,Model!$H$12:$AM$12)=0,"n.a.",SUMIF(Model!$H$10:$AM$10,C44,Model!$H$12:$AM$12)) -> 4.106589 | E44: =IF(SUMIF(Model!$H$10:$AM$10,C44,Model!$H$16:$AM$16)=0,"n.a.",SUMIF(Model!$H$10:$AM$10,C44,Model!$H$16:$AM$16)) -> 6.85 | F44: =+N(E44>D44) -> 1 | K44: Debt EoP | M44: =Model!L109 -> 256.5 | N44: =+N41+N42+N43 -> 267.14142 | O44: =+O41+O42+O43 -> 291.64354 | P44: =+P41+P42+P43 -> 304.19406 | Q44: =+Q41+Q42+Q43 -> 304.19406 | R44: =+R41+R42+R43 -> 304.19406 | S44: =+S41+S42+S43 -> 304.19406 | T44: =+T41+T42+T43 -> 0
...

Sheet Model
C2: =RIGHT(CELL("filename",C1), LEN(CELL("filename", C1))- FIND("]", CELL("filename", C1), 1)) -> Model
C4: Closing | D4: 46022
C5: Year End | D5: 44561
C7: Credit metrics | H7: 2025 | L7: =+H7+1 -> 2026 | P7: =+L7+1 -> 2027 | T7: =+P7+1 -> 2028 | X7: =+T7+1 -> 2029 | AB7: =+X7+1 -> 2030 | AF7: =+AB7+1 -> 2031 | AJ7: =+AF7+1 -> 2032
H9: Q1 | I9: Q2 | J9: Q3 | K9: Closing | L9: Q1 | M9: Q2 | N9: Q3 | O9: Q4 | P9: Q1 | Q9: Q2 | R9: Q3 | S9: Q4 | T9: Q1 | U9: Q2 | V9: Q3 | W9: Q4 | X9: Q1 | Y9: Q2 | Z9: Q3 | AA9: Q4 | AB9: Q1 | AC9: Q2 | AD9: Q3 | AE9: Q4 | AF9: Q1 | AG9: Q2 | AH9: Q3 | AI9: Q4 | AJ9: Q1 | AK9: Q2 | AL9: Q3 | AM9: Q4
H10: 45747 | I10: 45838 | J10: 45930 | K10: 46022 | L10: =EOMONTH(K10,3) -> 46112 | M10: =EOMONTH(L10,3) -> 46203 | N10: =EOMONTH(M10,3) -> 46295 | O10: =EOMONTH(N10,3) -> 46387 | P10: =EOMONTH(O10,3) -> 46477 | Q10: =EOMONTH(P10,3) -> 46568 | R10: =EOMONTH(Q10,3) -> 46660 | S10: =EOMONTH(R10,3) -> 46752 | ... AM10: =EOMONTH(AL10,3) -> 48579
C12: Net leverage ratio (ND/EBITDA) | K12: =IF(K29=0,"n.a.",IF(K29<0,"n.a.",K29/K26)) -> 5 | L12: =IF(L29=0,"n.a.",IF(L29<0,"n.a.",L29/L26)) -> 4.8895653 | M12: =IF(M29=0,"n.a.",IF(M29<0,"n.a.",M29/M26)) -> 4.7806506 | N12: =IF(N29=0,"n.a.",IF(N29<0,"n.a.",N29/N26)) -> 4.6732351 | O12: =IF(O29=0,"n.a.",IF(O29<0,"n.a.",O29/O26)) -> 4.5672987 | P12: =IF(P29=0,"n.a.",IF(P29<0,"n.a.",P29/P26)) -> 4.3263966 | Q12: =IF(Q29=0,"n.a.",IF(Q29<0,"n.a.",Q29/Q26)) -> 4.106589 | R12: =IF(R29=0,"n.a.",IF(R29<0,"n.a.",R29/R26)) -> 3.9053511 | ... AM12: =IF(AM29=0,"n.a.",IF(AM29<0,"n.a.",AM29/AM26)) -> 2.0216804
C14: Headroom | D14: =+'Debt Structure'!D142 -> 0.4 | K14: =IF(K29=0,"n.a.",IF(K29<0,"n.a.",(K29/(K26*(1-$D$14))))) -> 8.3333333 | L14: =IF(L29=0,"n.a.",IF(L29<0,"n.a.",(L29/(L26*(1-$D$14))))) -> 8.1492755 | M14: =IF(M29=0,"n.a.",IF(M29<0,"n.a.",(M29/(M26*(1-$D$14))))) -> 7.967751 | N14: =IF(N29=0,"n.a.",IF(N29<0,"n.a.",(N29/(N26*(1-$D$14))))) -> 7.7887252 | O14: =IF(O29=0,"n.a.",IF(O29<0,"n.a.",(O29/(O26*(1-$D$14))))) -> 7.6121645 | P14: =IF(P29=0,"n.a.",IF(P29<0,"n.a.",(P29/(P26*(1-$D$14))))) -> 7.210661 | Q14: =IF(Q29=0,"n.a.",IF(Q29<0,"n.a.",(Q29/(Q26*(1-$D$14))))) -> 6.8443149 | R14: =IF(R29=0,"n.a.",IF(R29<0,"n.a.",(R29/(R26*(1-$D$14))))) -> 6.5089185 | ... AM14: =IF(AM29=0,"n.a.",IF(AM29<0,"n.a.",(AM29/(AM26*(1-$D$14))))) -> 3.3694674
C16: SFA Net Leverage Covenant | K16: =IFERROR(MAX($D$18,ROUNDUP((K14*100/5),0)*5/100),"n.a") -> 8.35 | L16: =IFERROR(MAX($D$18,ROUNDUP((L14*100/5),0)*5/100),"n.a") -> 8.15 | M16: =IFERROR(MAX($D$18,ROUNDUP((M14*100/5),0)*5/100),"n.a") -> 8 | N16: =IFERROR(MAX($D$18,ROUNDUP((N14*100/5),0)*5/100),"n.a") -> 7.8 | O16: =IFERROR(MAX($D$18,ROUNDUP((O14*100/5),0)*5/100),"n.a") -> 7.65 | P16: =IFERROR(MAX($D$18,ROUNDUP((P14*100/5),0)*5/100),"n.a") -> 7.25 | Q16: =IFERROR(MAX($D$18,ROUNDUP((Q14*100/5),0)*5/100),"n.a") -> 6.85 | R16: =IFERROR(MAX($D$18,ROUNDUP((R14*100/5),0)*5/100),"n.a") -> 6.55 | ... AM16: =IFERROR(MAX($D$18,ROUNDUP((AM14*100/5),0)*5/100),"n.a") -> 3.4
L17: =+L16>L12 -> TRUE | M17: =+M16>M12 -> TRUE | N17: =+N16>N12 -> TRUE | O17: =+O16>O12 -> TRUE | P17: =+P16>P12 -> TRUE | Q17: =+Q16>Q12 -> TRUE | R17: =+R16>R12 -> TRUE | S17: =+S16>S12 -> TRUE | ... AM17: =+AM16>AM12 -> TRUE
C18: Flattening of Net Leverage Covenant | D18: 3
C20: Covenant Source Data | H20: 2025 | L20: =+H20+1 -> 2026 | P20: =+L20+1 -> 2027 | T20: =+P20+1 -> 2028 | X20: =+T20+1 -> 2029 | AB20: =+X20+1 -> 2030 | AF20: =+AB20+1 -> 2031 | AJ20: =+AF20+1 -> 2032
H22: Q1 | I22: Q2 | J22: Q3 | K22: Closing | L22: Q1 | M22: Q2 | N22: Q3 | O22: Q4 | P22: Q1 | Q22: Q2 | R22: Q3 | S22: Q4 | T22: Q1 | U22: Q2 | V22: Q3 | W22: Q4 | X22: Q1 | Y22: Q2 | Z22: Q3 | AA22: Q4 | AB22: Q1 | AC22: Q2 | AD22: Q3 | AE22: Q4 | AF22: Q1 | AG22: Q2 | AH22: Q3 | AI22: Q4 | AJ22: Q1 | AK22: Q2 | AL22: Q3 | AM22: Q4
H23: 45747 | I23: 45838 | J23: 45930 | K23: 46022 | L23: =EOMONTH(K23,3) -> 46112 | M23: =EOMONTH(L23,3) -> 46203 | N23: =EOMONTH(M23,3) -> 46295 | O23: =EOMONTH(N23,3) -> 46387 | P23: =EOMONTH(O23,3) -> 46477 | Q23: =EOMONTH(P23,3) -> 46568 | R23: =EOMONTH(Q23,3) -> 46660 | S23: =EOMONTH(R23,3) -> 46752 | ... AM23: =EOMONTH(AL23,3) -> 48579
C25: EBITDA | H25: =H54 -> 12.825 | I25: =I54 -> 12.825 | J25: =J54 -> 12.825 | K25: =K54 -> 12.825 | L25: =M54 -> 13.06083 | M25: =N54 -> 13.06083 | N25: =O54 -> 13.06083 | O25: =P54 -> 13.06083 | P25: =R54 -> 15.428321 | Q25: =S54 -> 15.428321 | R25: =T54 -> 15.428321 | S25: =U54 -> 15.428321 | T25: =W54 -> 18.321271 | U25: =X54 -> 18.321271 | V25: =Y54 -> 18.321271 | W25: =Z54 -> 18.321271 | X25: =AB54 -> 19.896938 | Y25: =AC54 -> 19.896938 | Z25: =AD54 -> 19.896938 | AA25: =AE54 -> 19.896938 | AB25: =AG54 -> 21.945906 | AC25: =AH54 -> 21.945906 | AD25: =AI54 -> 21.945906 | AE25: =AJ54 -> 21.945906 | AF25: =AL54 -> 22.384824 | AG25: =AM54 -> 22.384824 | AH25: =AN54 -> 22.384824 | AI25: =AO54 -> 22.384824 | AJ25: =+AQ54 -> 22.832521 | AK25: =+AR54 -> 22.832521 | AL25: =+AS54 -> 22.832521 | AM25: =+AT54 -> 22.832521
C26: LTM EBITDA | H26: =H25+G25+F25+E25 -> 12.825 | I26: =I25+H25+G25+F25 -> 25.65 | J26: =J25+I25+H25+G25 -> 38.475 | K26: =+'Active Case'!F17 -> 51.3 | L26: =L25+K25+J25+I25 -> 51.53583 | M26: =M25+L25+K25+J25 -> 51.77166 | N26: =N25+M25+L25+K25 -> 52.007489 | O26: =O25+N25+M25+L25 -> 52.243319 | P26: =P25+O25+N25+M25 -> 54.610811 | Q26: =Q25+P25+O25+N25 -> 56.978302 | R26: =R25+Q25+P25+O25 -> 59.345794 | S26: =S25+R25+Q25+P25 -> 61.713285 | ... AM26: =AM25+AL25+AK25+AJ25 -> 91.330082
C27: Cash Balance | H27: =H102 -> 0 | I27: =I102 -> 0 | J27: =J102 -> 0 | K27: =L102 -> 0 | L27: =M102 -> 7.1725498 | M27: =N102 -> 14.318496 | N27: =O102 -> 21.437839 | O27: =Q102 -> 28.530578 | P27: =R102 -> 36.998923 | Q27: =S102 -> 45.406014 | R27: =T102 -> 53.751848 | S27: =V102 -> 62.036428 | T27: =W102 -> 68.526203 | U27: =X102 -> 74.984601 | V27: =Y102 -> 81.411623 | W27: =AA102 -> 87.807268 | X27: =AB102 -> 68.355451 | Y27: =AC102 -> 48.903634 | Z27: =AD102 -> 29.451817 | AA27: =AF102 -> 10 | AB27: =AG102 -> 16.882902 | AC27: =AH102 -> 23.765804 | AD27: =AI102 -> 30.648707 | AE27: =AK102 -> 37.531609 | AF27: =AL102 -> 45.00914 | AG27: =AM102 -> 52.486672 | AH27: =AN102 -> 59.964204 | AI27: =AP102 -> 67.441735 | AJ27: =AQ102 -> 79.954376 | AK27: =AR102 -> 92.467017 | AL27: =AS102 -> 104.97966 | AM27: =AU102 -> -184.64024
C28: Total Debt | H28: =H109 -> 0 | I28: =I109 -> 0 | J28: =J109 -> 0 | K28: =L109 -> 256.5 | L28: =M109 -> 259.16036 | M28: =N109 -> 261.82071 | N28: =O109 -> 264.48107 | O28: =Q109 -> 267.14142 | P28: =R109 -> 273.26695 | Q28: =S109 -> 279.39248 | R28: =T109 -> 285.51801 | S28: =V109 -> 291.64354 | T28: =W109 -> 294.78117 | U28: =X109 -> 297.9188 | V28: =Y109 -> 301.05643 | W28: =AA109 -> 304.19406 | X28: =AB109 -> 304.19406 | Y28: =AC109 -> 304.19406 | Z28: =AD109 -> 304.19406 | AA28: =AF109 -> 304.19406 | AB28: =AG109 -> 304.19406 | AC28: =AH109 -> 304.19406 | AD28: =AI109 -> 304.19406 | AE28: =AK109 -> 304.19406 | AF28: =AL109 -> 304.19406 | AG28: =AM109 -> 304.19406 | AH28: =AN109 -> 304.19406 | AI28: =AP109 -> 304.19406 | AJ28: =AQ109 -> 304.19406 | AK28: =AR109 -> 304.19406 | AL28: =AS109 -> 304.19406 | AM28: =AU109 -> 0
C29: Net Total Debt | H29: =H28-H27 -> 0 | I29: =I28-I27 -> 0 | J29: =J28-J27 -> 0 | K29: =K28-K27 -> 256.5 | L29: =L28-L27 -> 251.98781 | M29: =M28-M27 -> 247.50221 | N29: =N28-N27 -> 243.04323 | O29: =O28-O27 -> 238.61084 | ... AM29: =AM28-AM27 -> 184.64024
C31: Quarterly Model | H31: 2025 | M31: =+H31+1 -> 2026 | R31: =+M31+1 -> 2027 | W31: =+R31+1 -> 2028 | AB31: =+W31+1 -> 2029 | AG31: =+AB31+1 -> 2030 | AL31: =+AG31+1 -> 2031 | AQ31: =+AL31+1 -> 2032
C33: Seasonality
H35: Q1 | I35: Q2 | J35: Q3 | K35: Closing | L35: FY | M35: Q1 | N35: Q2 | O35: Q3 | P35: Q4 | Q35: FY | R35: Q1 | S35: Q2 | T35: Q3 | U35: Q4 | V35: FY | W35: Q1 | X35: Q2 | Y35: Q3 | Z35: Q4 | AA35: FY | AB35: Q1 | AC35: Q2 | AD35: Q3 | AE35: Q4 | AF35: FY | AG35: Q1 | AH35: Q2 | AI35: Q3 | AJ35: Q4 | AK35: FY | AL35: Q1 | AM35: Q2 | AN35: Q3 | AO35: Q4 | AP35: FY | AQ35: Q1 | AR35: Q2 | AS35: Q3 | AT35: Q4 | AU35: FY
H36: 45747 | I36: 45838 | J36: 45930 | K36: 46022 | L36: =K36 -> 46022 | M36: =EOMONTH(L36,3) -> 46112 | N36: =EOMONTH(M36,3) -> 46203 | O36: =EOMONTH(N36,3) -> 46295 | P36: =EOMONTH(O36,3) -> 46387 | Q36: =P36 -> 46387 | R36: =EOMONTH(Q36,3) -> 46477 | S36: =EOMONTH(R36,3) -> 46568 | T36: =EOMONTH(S36,3) -> 46660 | U36: =EOMONTH(T36,3) -> 46752 | V36: =U36 -> 46752 | W36: =EOMONTH(V36,3) -> 46843 | X36: =EOMONTH(W36,3) -> 46934 | Y36: =EOMONTH(X36,3) -> 47026 | Z36: =EOMONTH(Y36,3) -> 47118 | AA36: =Z36 -> 47118 | AB36: =EOMONTH(AA36,3) -> 47208 | AC36: =EOMONTH(AB36,3) -> 47299 | AD36: =EOMONTH(AC36,3) -> 47391 | AE36: =EOMONTH(AD36,3) -> 47483 | AF36: =AE36 -> 47483 | AG36: =EOMONTH(AF36,3) -> 47573 | AH36: =EOMONTH(AG36,3) -> 47664 | AI36: =EOMONTH(AH36,3) -> 47756 | AJ36: =EOMONTH(AI36,3) -> 47848 | AK36: =AJ36 -> 47848 | AL36: =EOMONTH(AK36,3) -> 47938 | AM36: =EOMONTH(AL36,3) -> 48029 | AN36: =EOMONTH(AM36,3) -> 48121 | AO36: =EOMONTH(AN36,3) -> 48213 | AP36: =AO36 -> 48213 | AQ36: =EOMONTH(AP36,3) -> 48304 | AR36: =EOMONTH(AQ36,3) -> 48395 | AS36: =EOMONTH(AR36,3) -> 48487 | AT36: =EOMONTH(AS36,3) -> 48579 | AU36: =AT36 -> 48579
C38: Revenue | H38: 0.25 | I38: 0.25 | J38: 0.25 | K38: 0.25 | L38: =SUM(H38:K38) -> 1 | M38: 0.25 | N38: 0.25 | O38: 0.25 | P38: 0.25 | Q38: =SUM(M38:P38) -> 1 | R38: 0.25 | S38: 0.25 | T38: 0.25 | U38: 0.25 | V38: =SUM(R38:U38) -> 1 | W38: 0.25 | X38: 0.25 | Y38: 0.25 | Z38: 0.25 | AA38: =SUM(W38:Z38) -> 1 | AB38: 0.25 | AC38: 0.25 | AD38: 0.25 | AE38: 0.25 | AF38: =SUM(AB38:AE38) -> 1 | AG38: 0.25 | AH38: 0.25 | AI38: 0.25 | AJ38: 0.25 | AK38: =SUM(AG38:AJ38) -> 1 | AL38: 0.25 | AM38: 0.25 | AN38: 0.25 | AO38: 0.25 | AP38: =SUM(AL38:AO38) -> 1 | AQ38: 0.25 | AR38: 0.25 | AS38: 0.25 | AT38: 0.25 | AU38: =SUM(AQ38:AT38) -> 1
C39: EBITDA | H39: 0.25 | I39: 0.25 | J39: 0.25 | K39: 0.25 | L39: =SUM(H39:K39) -> 1 | M39: 0.25 | N39: 0.25 | O39: 0.25 | P39: 0.25 | Q39: =SUM(M39:P39) -> 1 | R39: 0.25 | S39: 0.25 | T39: 0.25 | U39: 0.25 | V39: =SUM(R39:U39) -> 1 | W39: 0.25 | X39: 0.25 | Y39: 0.25 | Z39: 0.25 | AA39: =SUM(W39:Z39) -> 1 | AB39: 0.25 | AC39: 0.25 | AD39: 0.25 | AE39: 0.25 | AF39: =SUM(AB39:AE39) -> 1 | AG39: 0.25 | AH39: 0.25 | AI39: 0.25 | AJ39: 0.25 | AK39: =SUM(AG39:AJ39) -> 1 | AL39: 0.25 | AM39: 0.25 | AN39: 0.25 | AO39: 0.25 | AP39: =SUM(AL39:AO39) -> 1 | AQ39: 0.25 | AR39: 0.25 | AS39: 0.25 | AT39: 0.25 | AU39: =SUM(AQ39:AT39) -> 1
C40: D&A | H40: 0.25 | I40: 0.25 | J40: 0.25 | K40: 0.25 | L40: =SUM(H40:K40) -> 1 | M40: 0.25 | N40: 0.25 | O40: 0.25 | P40: 0.25 | Q40: =SUM(M40:P40) -> 1 | R40: 0.25 | S40: 0.25 | T40: 0.25 | U40: 0.25 | V40: =SUM(R40:U40) -> 1 | W40: 0.25 | X40: 0.25 | Y40: 0.25 | Z40: 0.25 | AA40: =SUM(W40:Z40) -> 1 | AB40: 0.25 | AC40: 0.25 | AD40: 0.25 | AE40: 0.25 | AF40: =SUM(AB40:AE40) -> 1 | AG40: 0.25 | AH40: 0.25 | AI40: 0.25 | AJ40: 0.25 | AK40: =SUM(AG40:AJ40) -> 1 | AL40: 0.25 | AM40: 0.25 | AN40: 0.25 | AO40: 0.25 | AP40: =SUM(AL40:AO40) -> 1 | AQ40: 0.25 | AR40: 0.25 | AS40: 0.25 | AT40: 0.25 | AU40: =SUM(AQ40:AT40) -> 1
C41: Taxes | H41: 0.25 | I41: 0.25 | J41: 0.25 | K41: 0.25 | L41: =SUM(H41:K41) -> 1 | M41: 0.25 | N41: 0.25 | O41: 0.25 | P41: 0.25 | Q41: =SUM(M41:P41) -> 1 | R41: 0.25 | S41: 0.25 | T41: 0.25 | U41: 0.25 | V41: =SUM(R41:U41) -> 1 | W41: 0.25 | X41: 0.25 | Y41: 0.25 | Z41: 0.25 | AA41: =SUM(W41:Z41) -> 1 | AB41: 0.25 | AC41: 0.25 | AD41: 0.25 | AE41: 0.25 | AF41: =SUM(AB41:AE41) -> 1 | AG41: 0.25 | AH41: 0.25 | AI41: 0.25 | AJ41: 0.25 | AK41: =SUM(AG41:AJ41) -> 1 | AL41: 0.25 | AM41: 0.25 | AN41: 0.25 | AO41: 0.25 | AP41: =SUM(AL41:AO41) -> 1 | AQ41: 0.25 | AR41: 0.25 | AS41: 0.25 | AT41: 0.25 | AU41: =SUM(AQ41:AT41) -> 1
C42: Working Capital | H42: 0.25 | I42: 0.25 | J42: 0.25 | K42: 0.25 | L42: =SUM(H42:K42) -> 1 | M42: 0.25 | N42: 0.25 | O42: 0.25 | P42: 0.25 | Q42: =SUM(M42:P42) -> 1 | R42: 0.25 | S42: 0.25 | T42: 0.25 | U42: 0.25 | V42: =SUM(R42:U42) -> 1 | W42: 0.25 | X42: 0.25 | Y42: 0.25 | Z42: 0.25 | AA42: =SUM(W42:Z42) -> 1 | AB42: 0.25 | AC42: 0.25 | AD42: 0.25 | AE42: 0.25 | AF42: =SUM(AB42:AE42) -> 1 | AG42: 0.25 | AH42: 0.25 | AI42: 0.25 | AJ42: 0.25 | AK42: =SUM(AG42:AJ42) -> 1 | AL42: 0.25 | AM42: 0.25 | AN42: 0.25 | AO42: 0.25 | AP42: =SUM(AL42:AO42) -> 1 | AQ42: 0.25 | AR42: 0.25 | AS42: 0.25 | AT42: 0.25 | AU42: =SUM(AQ42:AT42) -> 1
C43: Capex | H43: 0.25 | I43: 0.25 | J43: 0.25 | K43: 0.25 | L43: =SUM(H43:K43) -> 1 | M43: 0.25 | N43: 0.25 | O43: 0.25 | P43: 0.25 | Q43: =SUM(M43:P43) -> 1 | R43: 0.25 | S43: 0.25 | T43: 0.25 | U43: 0.25 | V43: =SUM(R43:U43) -> 1 | W43: 0.25 | X43: 0.25 | Y43: 0.25 | Z43: 0.25 | AA43: =SUM(W43:Z43) -> 1 | AB43: 0.25 | AC43: 0.25 | AD43: 0.25 | AE43: 0.25 | AF43: =SUM(AB43:AE43) -> 1 | AG43: 0.25 | AH43: 0.25 | AI43: 0.25 | AJ43: 0.25 | AK43: =SUM(AG43:AJ43) -> 1 | AL43: 0.25 | AM43: 0.25 | AN43: 0.25 | AO43: 0.25 | AP43: =SUM(AL43:AO43) -> 1 | AQ43: 0.25 | AR43: 0.25 | AS43: 0.25 | AT43: 0.25 | AU43: =SUM(AQ43:AT43) -> 1
C44: Dividends | H44: 0.25 | I44: 0.25 | J44: 0.25 | K44: 0.25 | L44: =SUM(H44:K44) -> 1 | M44: 0.25 | N44: 0.25 | O44: 0.25 | P44: 0.25 | Q44: =SUM(M44:P44) -> 1 | R44: 0.25 | S44: 0.25 | T44: 0.25 | U44: 0.25 | V44: =SUM(R44:U44) -> 1 | W44: 0.25 | X44: 0.25 | Y44: 0.25 | Z44: 0.25 | AA44: =SUM(W44:Z44) -> 1 | AB44: 0.25 | AC44: 0.25 | AD44: 0.25 | AE44: 0.25 | AF44: =SUM(AB44:AE44) -> 1 | AG44: 0.25 | AH44: 0.25 | AI44: 0.25 | AJ44: 0.25 | AK44: =SUM(AG44:AJ44) -> 1 | AL44: 0.25 | AM44: 0.25 | AN44: 0.25 | AO44: 0.25 | AP44: =SUM(AL44:AO44) -> 1 | AQ44: 0.25 | AR44: 0.25 | AS44: 0.25 | AT44: 0.25 | AU44: =SUM(AQ44:AT44) -> 1
C45: Current debt | H45: 0.25 | I45: 0.25 | J45: 0.25 | K45: 0.25 | L45: =SUM(H45:K45) -> 1 | M45: 0.25 | N45: 0.25 | O45: 0.25 | P45: 0.25 | Q45: =SUM(M45:P45) -> 1 | R45: 0.25 | S45: 0.25 | T45: 0.25 | U45: 0.25 | V45: =SUM(R45:U45) -> 1 | W45: 0.25 | X45: 0.25 | Y45: 0.25 | Z45: 0.25 | AA45: =SUM(W45:Z45) -> 1 | AB45: 0.25 | AC45: 0.25 | AD45: 0.25 | AE45: 0.25 | AF45: =SUM(AB45:AE45) -> 1 | AG45: 0.25 | AH45: 0.25 | AI45: 0.25 | AJ45: 0.25 | AK45: =SUM(AG45:AJ45) -> 1 | AL45: 0.25 | AM45: 0.25 | AN45: 0.25 | AO45: 0.25 | AP45: =SUM(AL45:AO45) -> 1 | AQ45: 0.25 | AR45: 0.25 | AS45: 0.25 | AT45: 0.25 | AU45: =SUM(AQ45:AT45) -> 1
C47: P&L
H49: Q1 | I49: Q2 | J49: Q3 | K49: Closing | L49: FY | M49: Q1 | N49: Q2 | O49: Q3 | P49: Q4 | Q49: FY | R49: Q1 | S49: Q2 | T49: Q3 | U49: Q4 | V49: FY | W49: Q1 | X49: Q2 | Y49: Q3 | Z49: Q4 | AA49: FY | AB49: Q1 | AC49: Q2 | AD49: Q3 | AE49: Q4 | AF49: FY | AG49: Q1 | AH49: Q2 | AI49: Q3 | AJ49: Q4 | AK49: FY | AL49: Q1 | AM49: Q2 | AN49: Q3 | AO49: Q4 | AP49: FY | AQ49: Q1 | AR49: Q2 | AS49: Q3 | AT49: Q4 | AU49: FY
H50: 45747 | I50: 45838 | J50: 45930 | K50: 46022 | L50: =K50 -> 46022 | M50: =EOMONTH(L50,3) -> 46112 | N50: =EOMONTH(M50,3) -> 46203 | O50: =EOMONTH(N50,3) -> 46295 | P50: =EOMONTH(O50,3) -> 46387 | Q50: =P50 -> 46387 | R50: =EOMONTH(Q50,3) -> 46477 | S50: =EOMONTH(R50,3) -> 46568 | T50: =EOMONTH(S50,3) -> 46660 | U50: =EOMONTH(T50,3) -> 46752 | V50: =U50 -> 46752 | W50: =EOMONTH(V50,3) -> 46843 | X50: =EOMONTH(W50,3) -> 46934 | Y50: =EOMONTH(X50,3) -> 47026 | Z50: =EOMONTH(Y50,3) -> 47118 | AA50: =Z50 -> 47118 | AB50: =EOMONTH(AA50,3) -> 47208 | AC50: =EOMONTH(AB50,3) -> 47299 | AD50: =EOMONTH(AC50,3) -> 47391 | AE50: =EOMONTH(AD50,3) -> 47483 | AF50: =AE50 -> 47483 | AG50: =EOMONTH(AF50,3) -> 47573 | AH50: =EOMONTH(AG50,3) -> 47664 | AI50: =EOMONTH(AH50,3) -> 47756 | AJ50: =EOMONTH(AI50,3) -> 47848 | AK50: =AJ50 -> 47848 | AL50: =EOMONTH(AK50,3) -> 47938 | AM50: =EOMONTH(AL50,3) -> 48029 | AN50: =EOMONTH(AM50,3) -> 48121 | AO50: =EOMONTH(AN50,3) -> 48213 | AP50: =AO50 -> 48213 | AQ50: =EOMONTH(AP50,3) -> 48304 | AR50: =EOMONTH(AQ50,3) -> 48395 | AS50: =EOMONTH(AR50,3) -> 48487 | AT50: =EOMONTH(AS50,3) -> 48579 | AU50: =AT50 -> 48579
C52: Total Revenue | H52: =L52*H38 -> 66.917314 | I52: =L52*I38 -> 66.917314 | J52: =L52*J38 -> 66.917314 | K52: =L52*K38 -> 66.917314 | L52: ='Active Case'!F9 -> 267.66926 | M52: =Q52*M38 -> 75.159245 | N52: =Q52*N38 -> 75.159245 | O52: =Q52*O38 -> 75.159245 | P52: =Q52*P38 -> 75.159245 | Q52: ='Active Case'!G9 -> 300.63698 | R52: =V52*R38 -> 86.094911 | S52: =V52*S38 -> 86.094911 | T52: =V52*T38 -> 86.094911 | U52: =V52*U38 -> 86.094911 | V52: ='Active Case'!H9 -> 344.37965 | W52: =AA52*W38 -> 96.605186 | X52: =AA52*X38 -> 96.605186 | Y52: =AA52*Y38 -> 96.605186 | Z52: =AA52*Z38 -> 96.605186 | AA52: ='Active Case'!I9 -> 386.42074 | AB52: =AF52*AB38 -> 102.79279 | AC52: =AF52*AC38 -> 102.79279 | AD52: =AF52*AD38 -> 102.79279 | AE52: =AF52*AE38 -> 102.79279 | AF52: ='Active Case'!J9 -> 411.17115 | AG52: =AK52*AG38 -> 109.66452 | AH52: =AK52*AH38 -> 109.66452 | AI52: =AK52*AI38 -> 109.66452 | AJ52: =AK52*AJ38 -> 109.66452 | AK52: ='Active Case'!K9 -> 438.6581 | AL52: =AP52*AL38 -> 111.85782 | AM52: =AP52*AM38 -> 111.85782 | AN52: =AP52*AN38 -> 111.85782 | AO52: =AP52*AO38 -> 111.85782 | AP52: ='Active Case'!L9 -> 447.43126 | AQ52: =AU52*AQ38 -> 114.09497 | AR52: =AU52*AR38 -> 114.09497 | AS52: =AU52*AS38 -> 114.09497 | AT52: =AU52*AT38 -> 114.09497 | AU52: ='Active Case'!M9 -> 456.37989
C54: EBITDA | H54: =L54*H39 -> 12.825 | I54: =L54*I39 -> 12.825 | J54: =L54*J39 -> 12.825 | K54: =L54*K39 -> 12.825 | L54: =+'Active Case'!F17 -> 51.3 | M54: =Q54*M39 -> 13.06083 | N54: =Q54*N39 -> 13.06083 | O54: =Q54*O39 -> 13.06083 | P54: =Q54*P39 -> 13.06083 | Q54: ='Active Case'!G17 -> 52.243319 | R54: =V54*R39 -> 15.428321 | S54: =V54*S39 -> 15.428321 | T54: =V54*T39 -> 15.428321 | U54: =V54*U39 -> 15.428321 | V54: ='Active Case'!H17 -> 61.713285 | W54: =AA54*W39 -> 18.321271 | X54: =AA54*X39 -> 18.321271 | Y54: =AA54*Y39 -> 18.321271 | Z54: =AA54*Z39 -> 18.321271 | AA54: ='Active Case'!I17 -> 73.285082 | AB54: =AF54*AB39 -> 19.896938 | AC54: =AF54*AC39 -> 19.896938 | AD54: =AF54*AD39 -> 19.896938 | AE54: =AF54*AE39 -> 19.896938 | AF54: ='Active Case'!J17 -> 79.587752 | AG54: =AK54*AG39 -> 21.945906 | AH54: =AK54*AH39 -> 21.945906 | AI54: =AK54*AI39 -> 21.945906 | AJ54: =AK54*AJ39 -> 21.945906 | AK54: ='Active Case'!K17 -> 87.783624 | AL54: =AP54*AL39 -> 22.384824 | AM54: =AP54*AM39 -> 22.384824 | AN54: =AP54*AN39 -> 22.384824 | AO54: =AP54*AO39 -> 22.384824 | AP54: ='Active Case'!L17 -> 89.539296 | AQ54: =AU54*AQ39 -> 22.832521 | AR54: =AU54*AR39 -> 22.832521 | AS54: =AU54*AS39 -> 22.832521 | AT54: =AU54*AT39 -> 22.832521 | AU54: ='Active Case'!M17 -> 91.330082
C55: D&A | H55: =L55*H40 -> -3.29669 | I55: =L55*I40 -> -3.29669 | J55: =L55*J40 -> -3.29669 | K55: =L55*K40 -> -3.29669 | L55: ='Active Case'!F20 -> -13.18676 | M55: =Q55*M40 -> -3.441725 | N55: =Q55*N40 -> -3.441725 | O55: =Q55*O40 -> -3.441725 | P55: =Q55*P40 -> -3.441725 | Q55: ='Active Case'!G20 -> -13.7669 | R55: =V55*R40 -> -3.6943183 | S55: =V55*S40 -> -3.6943183 | T55: =V55*T40 -> -3.6943183 | U55: =V55*U40 -> -3.6943183 | V55: ='Active Case'!H20 -> -14.777273 | W55: =AA55*W40 -> -3.9373269 | X55: =AA55*X40 -> -3.9373269 | Y55: =AA55*Y40 -> -3.9373269 | Z55: =AA55*Z40 -> -3.9373269 | AA55: ='Active Case'!I20 -> -15.749308 | AB55: =AF55*AB40 -> -4.0301323 | AC55: =AF55*AC40 -> -4.0301323 | AD55: =AF55*AD40 -> -4.0301323 | AE55: =AF55*AE40 -> -4.0301323 | AF55: ='Active Case'!J20 -> -16.120529 | AG55: =AK55*AG40 -> -4.077246 | AH55: =AK55*AH40 -> -4.077246 | AI55: =AK55*AI40 -> -4.077246 | AJ55: =AK55*AJ40 -> -4.077246 | AK55: ='Active Case'!K20 -> -16.308984 | AL55: =AP55*AL40 -> -4.077246 | AM55: =AP55*AM40 -> -4.077246 | AN55: =AP55*AN40 -> -4.077246 | AO55: =AP55*AO40 -> -4.077246 | AP55: ='Active Case'!L20 -> -16.308984 | AQ55: =AU55*AQ40 -> -4.077246 | AR55: =AU55*AR40 -> -4.077246 | AS55: =AU55*AS40 -> -4.077246 | AT55: =AU55*AT40 -> -4.077246 | AU55: ='Active Case'!M20 -> -16.308984
C56: EBIT | H56: =SUM(H54:H55) -> 9.52831 | I56: =SUM(I54:I55) -> 9.52831 | J56: =SUM(J54:J55) -> 9.52831 | K56: =SUM(K54:K55) -> 9.52831 | L56: =SUM(L54:L55) -> 38.11324 | M56: =SUM(M54:M55) -> 9.6191048 | N56: =SUM(N54:N55) -> 9.6191048 | O56: =SUM(O54:O55) -> 9.6191048 | ... AU56: =SUM(AU54:AU55) -> 75.021098
C58: Interest Expense (incl. commitment fees) | H58: =SUM(H59:H62) -> 0 | I58: =SUM(I59:I62) -> 0 | J58: =SUM(J59:J62) -> 0 | K58: =SUM(K59:K62) -> 0 | L58: =SUM(L59:L62) -> 0 | M58: =SUM(M59:M62) -> -3.7118513 | N58: =SUM(N59:N62) -> -3.7384549 | O58: =SUM(O59:O62) -> -3.7650584 | ... AU58: =SUM(AU59:AU62) -> -14.630678
C59: ='Debt Structure'!C22 -> TLA | H59: =H129 -> 0 | I59: =I129 -> 0 | J59: =J129 -> 0 | K59: =K129 -> 0 | L59: =SUM(H59:K59) -> 0 | M59: =M129 -> 0 | N59: =N129 -> 0 | O59: =O129 -> 0 | P59: =P129 -> 0 | Q59: =SUM(M59:P59) -> 0 | R59: =R129 -> 0 | S59: =S129 -> 0 | T59: =T129 -> 0 | U59: =U129 -> 0 | V59: =SUM(R59:U59) -> 0 | W59: =W129 -> 0 | X59: =X129 -> 0 | Y59: =Y129 -> 0 | Z59: =Z129 -> 0 | AA59: =SUM(W59:Z59) -> 0 | AB59: =AB129 -> 0 | AC59: =AC129 -> 0 | AD59: =AD129 -> 0 | AE59: =AE129 -> 0 | AF59: =SUM(AB59:AE59) -> 0 | AG59: =AG129 -> 0 | AH59: =AH129 -> 0 | AI59: =AI129 -> 0 | AJ59: =AJ129 -> 0 | AK59: =SUM(AG59:AJ59) -> 0 | AL59: =AL129 -> 0 | AM59: =AM129 -> 0 | AN59: =AN129 -> 0 | AO59: =AO129 -> 0 | AP59: =SUM(AL59:AO59) -> 0 | AQ59: =AQ129 -> 0 | AR59: =AR129 -> 0 | AS59: =AS129 -> 0 | AT59: =AT129 -> 0 | AU59: =SUM(AQ59:AT59) -> 0
...

Sheet Debt Structure
C2: =RIGHT(CELL("filename",D1), LEN(CELL("filename", D1))- FIND("]", CELL("filename", D1), 1)) -> Debt Structure | M2: TLB Only
C4: =+'Debt Summary'!D6 -> 46022 | M4: =+C4 -> 46022
C5: ACTIVE SCENARIO | M5: TLB
C7: Adj. normalized EBITDA | D7: =+'Active Case'!F17 -> 51.3 | M7: Adj. normalized EBITDA | N7: =+'Active Case'!F17 -> 51.3
C9: UPFRONT FEES | M9: UPFRONT FEES
D11: Amount | E11: UF Fees | F11: UF Fees (€k) | N11: Amount | O11: UF Fees | P11: UF Fees (€k)
C12: TLA | D12: =+N12 -> 0 | E12: =+O12 -> 0.015 | F12: =+P12 -> 0 | M12: TLA | N12: =N22 -> 0 | O12: 0.015 | P12: =O12*N12 -> 0
C13: TLB | D13: =+N13 -> 256.5 | E13: =+O13 -> 0.015 | F13: =+P13 -> 3.8475 | M13: TLB | N13: =N23 -> 256.5 | O13: 0.015 | P13: =O13*N13 -> 3.8475
C14: CAF | D14: =+N14 -> 50 | E14: =+O14 -> 0.015 | F14: =+P14 -> 0.75 | M14: CAF | N14: =N33 -> 50 | O14: 0.015 | P14: =O14*N14 -> 0.75
C15: RCF | D15: =+N15 -> 20 | E15: =+O15 -> 0.015 | F15: =+P15 -> 0.3 | M15: RCF | N15: =N32 -> 20 | O15: 0.015 | P15: =O15*N15 -> 0.3
C16: TOTAL | D16: =SUM(D12:D15) -> 326.5 | E16: =+O16 -> 0.015 | F16: =SUM(F12:F15) -> 4.8975 | M16: TOTAL | N16: =SUM(N12:N15) -> 326.5 | O16: =+P16/N16 -> 0.015 | P16: =SUM(P12:P15) -> 4.8975
C19: FINAL CAPITAL STRUCTURE | M19: FINAL CAPITAL STRUCTURE
C21: Capital Structure | D21: EURm | E21: xEBITDA | F21: Margin | G21: Maturity | M21: Capital Structure | N21: EURm | O21: xEBITDA | P21: Margin | Q21: Maturity
C22: TLA | D22: =+N22 -> 0 | E22: =+O22 -> 0 | F22: =+P22 -> 0 | G22: =+Q22 -> 46022 | H22: =+R22 -> 0 | M22: TLA | N22: =N7*O22 -> 0 | O22: 0 | P22: 0 | Q22: =+EOMONTH($M$4,R22*12) -> 46022 | R22: 0
C23: TLB | D23: =+N23 -> 256.5 | E23: =+O23 -> 5 | F23: =+P23 -> 0.035 | G23: =+Q23 -> 48579 | H23: =+R23 -> 7 | M23: TLB | N23: =N7*O23 -> 256.5 | O23: 5 | P23: 0.035 | Q23: =+EOMONTH($M$4,R23*12) -> 48579 | R23: 7
C24: Acquisition debt | D24: =SUM(D22:D23) -> 256.5 | E24: =+D24/D$7 -> 5 | M24: Acquisition debt | N24: =SUM(N22:N23) -> 256.5 | O24: =+N24/N$7 -> 5
C26: Cash | D26: =+N26 -> 0 | E26: =+O26 -> 0 | M26: Cash | N26: 0 | O26: =+N26/N$7 -> 0
C27: Total Net Debt | D27: =+D24+D26 -> 256.5 | E27: =+D27/D$7 -> 5 | M27: Total Net Debt | N27: =+N24+N26 -> 256.5 | O27: =+N27/$N7 -> 5
I28: C. Fee | S28: C. Fee
C29: PIK | D29: =+N29 -> 0 | E29: =+O29 -> 0 | M29: PIK | N29: =N7*O29 -> 0 | O29: 0
C30: Total Net Debt | D30: =+D27+D29 -> 256.5 | E30: =+D30/D$7 -> 5 | M30: Total Net Debt | N30: =+N27+N29 -> 256.5 | O30: =+N30/N$7 -> 5
C32: RCF | D32: =+N32 -> 20 | E32: =+O32 -> 0.38986355 | F32: =+P32 -> 0.03 | I32: =+S32 -> 0.01 | M32: RCF | N32: 20 | O32: =+N32/N$7 -> 0.38986355 | P32: 0.03 | S32: 0.01
C33: CAF | D33: =+N33 -> 50 | E33: =+O33 -> 0.97465887 | F33: =+P33 -> 0.03 | H33: =+R33 -> 3 | I33: =+S33 -> 0.01 | M33: CAF | N33: 50 | O33: =+N33/N$7 -> 0.97465887 | P33: 0.03 | R33: 3 | S33: 0.01
C34: Total | D34: =+D27+SUM(D32:D33) -> 326.5 | E34: =+D34/D$7 -> 6.3645224 | M34: Total | N34: =+N27+SUM(N32:N33) -> 326.5 | O34: =+N34/N$7 -> 6.3645224
C37: PERMITTED PAYMENTS/DIVIDENDS MECHANISIM | M37: PERMITTED PAYMENTS/DIVIDENDS MECHANISIM
D39: =+N39 -> Higher than | E39: =+O39 -> Lower than | F39: =+P39 -> % of FCF | N39: Higher than | O39: Lower than | P39: % of FCF
C40: =+M40 -> Range 1 | D40: =+N40 -> 4 | F40: =+P40 -> 0 | M40: Range 1 | N40: 4 | P40: 0
C41: =+M41 -> Range 2 | D41: =+N41 -> 3 | E41: =+O41 -> 4 | F41: =+P41 -> 0.5 | M41: Range 2 | N41: 3 | O41: =+N40 -> 4 | P41: 0.5
C42: =+M42 -> Range 3 | E42: =+O42 -> 3 | F42: =+P42 -> 1 | M42: Range 3 | O42: =+N41 -> 3 | P42: 1
C44: =+M44 -> Min Cash on Balance (€m) | D44: =+N44 -> 10 | M44: Min Cash on Balance (€m) | N44: 10
C47: SOURCES & USES | M47: SOURCES & USES
C49: Sources | D49: €m | F49: Uses | G49: €m | M49: Sources | N49: €m | P49: Uses | Q49: €m
C51: Equity ticket | D51: =+N51 -> 296.4975 | F51: Purchase Price | G51: 540 | M51: Equity ticket | N51: =+N56-SUM(N52:N55) -> 296.4975 | P51: Purchase Price | Q51: =+$G51 -> 540
C52: TLA | D52: =+N52 -> 0 | F52: Structuring fees | G52: =+Q52 -> 4.8975 | M52: TLA | N52: =+N22 -> 0 | P52: Structuring fees | Q52: =+P16 -> 4.8975
C53: TLB | D53: =+N53 -> 256.5 | M53: TLB | N53: =+N23 -> 256.5
C54: Holdco PIK | D54: =+N54 -> 0 | F54: Transaction cost | G54: =+Q54 -> 8.1 | M54: Holdco PIK | N54: =+N29 -> 0 | P54: Transaction cost | Q54: 8.1
C56: Total | D56: =+G56 -> 552.9975 | F56: Total | G56: =+SUM(G51:G55) -> 552.9975 | M56: Total | N56: =+Q56 -> 552.9975 | P56: Total | Q56: =+SUM(Q51:Q55) -> 552.9975
C59: AMORTIZATION PROFILE | M59: AMORTIZATION PROFILE
C61: Swap Rate (annual %) | D61: 0.02
C63: =C22 -> TLA | D63: % | F63: =C23 -> TLB | G63: % | I63: Euribor fwd | M63: =M22 -> TLA | N63: % | P63: =M23 -> TLB | Q63: %
...

Sheet Active Case
C2: =RIGHT(CELL("filename",C1), LEN(CELL("filename", C1))- FIND("]", CELL("filename", C1), 1)) -> Active Case
C4: FYE Dec (€m) | F4: FY25B | G4: FY26F | H4: FY27F | I4: FY28F | J4: FY29F | K4: FY30F | L4: FY31F | M4: FY32F | O4: FY25B-32F
F5: Seller case | G5: Seller case | H5: Seller case | I5: Seller case | J5: Seller case | K5: Seller case | L5: Seller case | M5: Seller case | O5: Cum. | P5: CAGR
B7: A. | C7: Income Statement
B9: 1. | C9: Net Revenues | F9: 267.66926 | G9: 300.63698 | H9: 344.37965 | I9: 386.42074 | J9: 411.17115 | K9: 438.6581 | L9: 447.43126 | M9: 456.37989 | O9: =+SUM(F9:K9) -> 2148.9359 | P9: =+IFERROR((K9/F9)^(1/5)-1,0) -> 0.10383849
C10: % Growth | G10: =G9/F9-1 -> 0.1231659 | H10: =H9/G9-1 -> 0.14549995 | I10: =I9/H9-1 -> 0.12207776 | J10: =J9/I9-1 -> 0.064050414 | K10: =K9/J9-1 -> 0.066850379 | L10: =L9/K9-1 -> 0.02 | M10: =M9/L9-1 -> 0.02
B12: 3. | C12: Reported EBITDA | F12: 45.111661 | G12: 52.243319 | H12: 61.713285 | I12: 73.285082 | J12: 79.587752 | K12: 87.783624 | L12: 89.539296 | M12: 91.330082 | O12: =+SUM(F12:K12) -> 399.72472 | P12: =+IFERROR((K12/F12)^(1/5)-1,0) -> 0.14241774
C13: % Margin | F13: =F12/F$9 -> 0.16853508 | G13: =G12/G$9 -> 0.17377543 | H13: =H12/H$9 -> 0.17920132 | I13: =I12/I$9 -> 0.18965101 | J13: =J12/J$9 -> 0.19356356 | K13: =K12/K$9 -> 0.20011855 | L13: =L12/L$9 -> 0.20011855 | M13: =M12/M$9 -> 0.20011855
C14: % Growth | G14: =G12/F12-1 -> 0.15808902 | H14: =H12/G12-1 -> 0.18126655 | I14: =I12/H12-1 -> 0.18750901 | J14: =J12/I12-1 -> 0.086002077 | K14: =K12/J12-1 -> 0.10297906 | L14: =L12/K12-1 -> 0.02 | M14: =M12/L12-1 -> 0.02
C16: Adjustments & normalizations | F16: 6.1883392 | G16: 0 | H16: 0 | I16: 0 | J16: 0 | K16: 0 | L16: 0 | M16: 0
B17: 3. | C17: Adj. normalized EBITDA | F17: =+F16+F12 -> 51.3 | G17: =+G16+G12 -> 52.243319 | H17: =+H16+H12 -> 61.713285 | I17: =+I16+I12 -> 73.285082 | J17: =+J16+J12 -> 79.587752 | K17: =+K16+K12 -> 87.783624 | L17: =+L16+L12 -> 89.539296 | M17: =+M16+M12 -> 91.330082 | O17: =+SUM(F17:K17) -> 405.91306 | P17: =+IFERROR((K17/F17)^(1/5)-1,0) -> 0.11342054
C20: D&A | F20: -13.18676 | G20: -13.7669 | H20: -14.777273 | I20: -15.749308 | J20: -16.120529 | K20: -16.308984 | L20: -16.308984 | M20: -16.308984 | O20: =+SUM(F20:K20) -> -89.909754 | P20: =+IFERROR((K20/F20)^(1/5)-1,0) -> 0.043416651
C21: % of Revenues | F21: =-F20/F$9 -> 0.049265127 | G21: =-G20/G$9 -> 0.045792437 | H21: =-H20/H$9 -> 0.042909834 | I21: =-I20/I$9 -> 0.04075689 | J21: =-J20/J$9 -> 0.039206372 | K21: =-K20/K$9 -> 0.037179262 | L21: =-L20/L$9 -> 0.036450256 | M21: =-M20/M$9 -> 0.035735546
C23: Taxes | F23: -8.2650988 | G23: -3.7039729 | H23: -5.6672515 | I23: -9.1167539 | J23: -10.349509 | K23: -12.041849 | L23: -12.687668 | M23: -14.216824 | O23: =+SUM(F23:K23) -> -49.144436 | P23: =+IFERROR((K23/F23)^(1/5)-1,0) -> 0.07817443
C24: % of Revenues | F24: =-F23/F$9 -> 0.030878028 | G24: =-G23/G$9 -> 0.012320417 | H24: =-H23/H$9 -> 0.016456407 | I24: =-I23/I$9 -> 0.023592817 | J24: =-J23/J$9 -> 0.025170806 | K24: =-K23/K$9 -> 0.02745156 | L24: =-L23/L$9 -> 0.028356688 | M24: =-M23/M$9 -> 0.031151294
B26: B. | C26: Cash Flow Statement
B28: 1. | C28: Reported EBITDA | F28: =+F12 -> 45.111661 | G28: =+G12 -> 52.243319 | H28: =+H12 -> 61.713285 | I28: =+I12 -> 73.285082 | J28: =+J12 -> 79.587752 | K28: =+K12 -> 87.783624 | L28: =+L12 -> 89.539296 | M28: =+M12 -> 91.330082 | O28: =+SUM(F28:K28) -> 399.72472 | P28: =+IFERROR((K28/F28)^(1/5)-1,0) -> 0.14241774
C30: Change in Working Capital | F30: -5.8299854 | G30: -5.0017419 | H30: -6.8476121 | I30: -6.1780846 | J30: -2.5470106 | K30: -2.9852206 | L30: -1.5660094 | M30: -1.5973296 | O30: =+SUM(F30:K30) -> -29.389655 | P30: =+IFERROR((K30/F30)^(1/5)-1,0) -> -0.12529463
C31: % of Total Revenues | F31: =F30/F$9 -> -0.021780557 | G31: =G30/G$9 -> -0.016637148 | H31: =H30/H$9 -> -0.019883905 | I31: =I30/I$9 -> -0.015987973 | J31: =J30/J$9 -> -0.0061945264 | K31: =K30/K$9 -> -0.0068053471 | L31: =L30/L$9 -> -0.0035 | M31: =M30/M$9 -> -0.0035
C33: Maintenance Capex | F33: -4.186 | G33: -6.0127396 | H33: -6.8875929 | I33: -7.7284148 | J33: -8.223423 | K33: -8.773162 | L33: -8.773162 | M33: -8.773162 | O33: =+SUM(F33:K33) -> -41.811332 | P33: =+IFERROR((K33/F33)^(1/5)-1,0) -> 0.15950169
C34: % of Total Revenues | F34: =F33/F$9 -> -0.015638703 | G34: =G33/G$9 -> -0.02 | H34: =H33/H$9 -> -0.02 | I34: =I33/I$9 -> -0.02 | J34: =J33/J$9 -> -0.02 | K34: =K33/K$9 -> -0.02 | L34: =L33/L$9 -> -0.019607843 | M34: =M33/M$9 -> -0.019223376
C36: Expansion Capex (no M&A) | F36: -9.62 | G36: -4.6286815 | H36: -17.614526 | I36: -4.8221098 | J36: -8.2464023 | K36: -2.2279714 | L36: 0 | M36: 0 | O36: =+SUM(F36:K36) -> -47.159691 | P36: =+IFERROR((K36/F36)^(1/5)-1,0) -> -0.25364249
C37: % of Total Revenues | F37: =F36/F$9 -> -0.035939876 | G37: =G36/G$9 -> -0.015396248 | H37: =H36/H$9 -> -0.051148568 | I37: =I36/I$9 -> -0.01247891 | J37: =J36/J$9 -> -0.020055888 | K37: =K36/K$9 -> -0.0050790613 | L37: =L36/L$9 -> 0 | M37: =M36/M$9 -> 0
B39: 2. | C39: Operating Pre-Tax Free Cash Flow | F39: =F28+F30+F33+F36 -> 25.475675 | G39: =G28+G30+G33+G36 -> 36.600156 | H39: =H28+H30+H33+H36 -> 30.363555 | I39: =I28+I30+I33+I36 -> 54.556473 | J39: =J28+J30+J33+J36 -> 60.570916 | K39: =K28+K30+K33+K36 -> 73.79727 | L39: =L28+L30+L33+L36 -> 79.200125 | M39: =M28+M30+M33+M36 -> 80.959591 | O39: =+SUM(F39:K39) -> 281.36405 | P39: =+IFERROR((K39/F39)^(1/5)-1,0) -> 0.23703765
C40: % Operating Pre-Tax FCF Margin | F40: =F39/F28 -> 0.56472484 | G40: =G39/G28 -> 0.70057104 | H40: =H39/H28 -> 0.49201002 | I40: =I39/I28 -> 0.74444173 | J40: =J39/J28 -> 0.76105826 | K40: =K39/K28 -> 0.8406724 | L40: =L39/L28 -> 0.88452923 | M40: =M39/M28 -> 0.88645043
B42: C. | C42: End
B48: D. | C48: Dividends
C51: Previous Year Leverage | G51: =+'Debt Summary'!M54 -> 5 | H51: =+'Debt Summary'!N54 -> 4.5672987 | I51: =+'Debt Summary'!O54 -> 3.7205459 | J51: =+'Debt Summary'!P54 -> 2.9526718 | K51: =+'Debt Summary'!Q54 -> 3.6964741 | L51: =+'Debt Summary'!R54 -> 3.0377244 | M51: =+'Debt Summary'!S54 -> 2.6441165
C52: Free Cash Flow | G52: =+N('Debt Summary'!N27>0)*'Debt Summary'!N27 -> 28.530578 | H52: =+N('Debt Summary'!O27>0)*'Debt Summary'!O27 -> 33.50585 | I52: =+N('Debt Summary'!P27>0)*'Debt Summary'!P27 -> 41.54168 | J52: =+N('Debt Summary'!Q27>0)*'Debt Summary'!Q27 -> 33.529203 | K52: =+N('Debt Summary'!R27>0)*'Debt Summary'!R27 -> 45.063218 | L52: =+N('Debt Summary'!S27>0)*'Debt Summary'!S27 -> 49.820253 | M52: =+N('Debt Summary'!T27>0)*'Debt Summary'!T27 -> 0
C53: Cash Balance BoP | G53: =+N('Debt Summary'!N32>0)*'Debt Summary'!N32 -> 0 | H53: =+N('Debt Summary'!O32>0)*'Debt Summary'!O32 -> 28.530578 | I53: =+N('Debt Summary'!P32>0)*'Debt Summary'!P32 -> 62.036428 | J53: =+N('Debt Summary'!Q32>0)*'Debt Summary'!Q32 -> 87.807268 | K53: =+N('Debt Summary'!R32>0)*'Debt Summary'!R32 -> 10 | L53: =+N('Debt Summary'!S32>0)*'Debt Summary'!S32 -> 37.531609 | M53: =+N('Debt Summary'!T32>0)*'Debt Summary'!T32 -> 67.441735
C54: Max Distributable Cash | G54: =+SUM(G52:G53)*N(G52>0) -> 28.530578 | H54: =+SUM(H52:H53)*N(H52>0) -> 62.036428 | I54: =+SUM(I52:I53)*N(I52>0) -> 103.57811 | J54: =+SUM(J52:J53)*N(J52>0) -> 121.33647 | K54: =+SUM(K52:K53)*N(K52>0) -> 55.063218 | L54: =+SUM(L52:L53)*N(L52>0) -> 87.351862 | M54: =+SUM(M52:M53)*N(M52>0) -> 0
C55: Minimum Cash on Balance | F55: =+'Debt Structure'!$D$44 -> 10 | G55: =+$F55 -> 10 | H55: =+$F55 -> 10 | I55: =+$F55 -> 10 | J55: =+$F55 -> 10 | K55: =+$F55 -> 10 | L55: =+$F55 -> 10 | M55: =+$F55 -> 10
C56: Distributable Cash | G56: =+MAX(G54-G55,0) -> 18.530578 | H56: =+MAX(H54-H55,0) -> 52.036428 | I56: =+MAX(I54-I55,0) -> 93.578108 | J56: =+MAX(J54-J55,0) -> 111.33647 | K56: =+MAX(K54-K55,0) -> 45.063218 | L56: =+MAX(L54-L55,0) -> 77.351862 | M56: =+MAX(M54-M55,0) -> 0
C58: Permitted Distributions under TLB Only structure:
D59: Higher than | E59: Lower than | F59: % Div | O59: Total
C60: Dividend Distribution - Range 1 | D60: =+'Debt Structure'!$D$40 -> 4 | F60: =+'Debt Structure'!$F$40 -> 0 | G60: =+N(G$51>$D60)*$F60*(G$56-G53) -> 0 | H60: =+N(H$51>$D60)*$F60*(H$56-H53) -> 0 | I60: =+N(I$51>$D60)*$F60*(I$56-I53) -> 0 | J60: =+N(J$51>$D60)*$F60*(J$56-J53) -> 0 | K60: =+N(K$51>$D60)*$F60*(K$56-K53) -> 0 | L60: =+N(L$51>$D60)*$F60*(L$56-L53) -> 0 | M60: =+N(M$51>$D60)*$F60*(M$56-M53) -> 0
C61: Dividend Distribution - Range 2 | D61: =+'Debt Structure'!$D$41 -> 3 | E61: =+'Debt Structure'!$E$41 -> 4 | F61: =+'Debt Structure'!$F$41 -> 0.5 | G61: =+N(AND(G$51>$D61,G$51<=$E61))*(G$56-G53)*$F61 -> 0 | H61: =+N(AND(H$51>$D61,H$51<=$E61))*(H$56-H53)*$F61 -> 0 | I61: =+N(AND(I$51>$D61,I$51<=$E61))*(I$56-I53)*$F61 -> 15.77084 | J61: =+N(AND(J$51>$D61,J$51<=$E61))*(J$56-J53)*$F61 -> 0 | K61: =+N(AND(K$51>$D61,K$51<=$E61))*(K$56-K53)*$F61 -> 17.531609 | L61: =+N(AND(L$51>$D61,L$51<=$E61))*(L$56-L53)*$F61 -> 19.910127 | M61: =+N(AND(M$51>$D61,M$51<=$E61))*(M$56-M53)*$F61 -> 0
C62: Dividend Distribution - Range 3 | E62: =+'Debt Structure'!$E$42 -> 3 | F62: =+'Debt Structure'!$F$42 -> 1 | G62: =+N(G$51<=$E62)*$F62*(G$56) -> 0 | H62: =+N(H$51<=$E62)*$F62*(H$56) -> 0 | I62: =+N(I$51<=$E62)*$F62*(I$56) -> 0 | J62: =+N(J$51<=$E62)*$F62*(J$56) -> 111.33647 | K62: =+N(K$51<=$E62)*$F62*(K$56) -> 0 | L62: =+N(L$51<=$E62)*$F62*(L$56) -> 0 | M62: =+N(M$51<=$E62)*$F62*(M$56) -> 0
C63: Applicable Dividend Distribution | G63: =+MAX(SUM(G60:G62),0) -> 0 | H63: =+MAX(SUM(H60:H62),0) -> 0 | I63: =+MAX(SUM(I60:I62),0) -> 15.77084 | J63: =+MAX(SUM(J60:J62),0) -> 111.33647 | K63: =+MAX(SUM(K60:K62),0) -> 17.531609 | L63: =+MAX(SUM(L60:L62),0) -> 19.910127 | M63: =+MAX(SUM(M60:M62),0) -> 0 | O63: =+SUM(G63:M63) -> 164.54905
C65: Active Case Distributions | G65: =+G63 -> 0 | H65: =+H63 -> 0 | I65: =+I63 -> 15.77084 | J65: =+J63 -> 111.33647 | K65: =+K63 -> 17.531609 | L65: =+L63 -> 19.910127 | M65: =+M63 -> 0 | O65: =+SUM(G65:M65) -> 164.54905

Sheet Tax Model
B2: =RIGHT(CELL("filename",B1), LEN(CELL("filename", B1))- FIND("]", CELL("filename", B1), 1)) -> Tax Model
H4: 45657 | I4: =EDATE(H4,12) -> 46022 | J4: =EDATE(I4,12) -> 46387 | K4: =EDATE(J4,12) -> 46752 | L4: =EDATE(K4,12) -> 47118 | M4: =EDATE(L4,12) -> 47483 | N4: =EDATE(M4,12) -> 47848 | O4: =EDATE(N4,12) -> 48213 | P4: =EDATE(O4,12) -> 48579
B6: 1 | D6: CIT Calculation
D8: EBITDA | I8: ='Active Case'!F28 -> 45.111661 | J8: ='Active Case'!G28 -> 52.243319 | K8: ='Active Case'!H28 -> 61.713285 | L8: ='Active Case'!I28 -> 73.285082 | M8: ='Active Case'!J28 -> 79.587752 | N8: ='Active Case'!K28 -> 87.783624 | O8: ='Active Case'!L28 -> 89.539296 | P8: ='Active Case'!M28 -> 91.330082
D9: D&A | I9: ='Active Case'!F20 -> -13.18676 | J9: ='Active Case'!G20 -> -13.7669 | K9: ='Active Case'!H20 -> -14.777273 | L9: ='Active Case'!I20 -> -15.749308 | M9: ='Active Case'!J20 -> -16.120529 | N9: ='Active Case'!K20 -> -16.308984 | O9: ='Active Case'!L20 -> -16.308984 | P9: ='Active Case'!M20 -> -16.308984
