Workbook

Sheet Instructions
B1: Project Galicia — Inditex (ITX.MC) | F1: Private & Confidential
B2: LBO Model — Instructions & Architecture Guide
C4: Step | D4: Reference Block (Linked) | E4: Explanation & Modeling Guidelines (Blue Font = User Input)
C5: 1 | D5: =+LBO!D9 -> Active Scenario Selector | E5: Scenario & Operating Drivers (Rows 7-17): Select Active Case in cell F9 (1 = Base, 2 = Bull, 3 = Bear) and customize scenario presets in E10:G17 (blue cells). Historical FY22A-FY25A figures are audited from Inditex Consolidated Annual Reports.
C6: 2 | D6: =+LBO!D21 -> Revenues | E6: Operating P&L & Pre-IFRS 16 Cash EBITDA Bridge (Rows 19-36): Projects Revenues, Gross Margin, and OpEx across FY26E-FY30E. Reconciles Reported Post-IFRS 16 EBITDA to Pre-IFRS 16 Cash EBITDA by deducting Fixed Cash Lease Outflows (Note 16 / CF Statement: €1,834m in FY25A; variable turnover rent of €670m is already inside OpEx).
C7: 3 | D7: =+LBO!D42 -> WK (Operating Working Capital) | E7: Operating Working Capital Schedule (Rows 42-48): Models Inventory, Receivables, and Payables as % of Revenues. Inditex operates with structural negative working capital (-€4,172m in FY25A, -10.5% of sales), so top-line growth generates positive cash inflows (-ΔWK).
C8: 4 | D8: =+LBO!D51 -> Capex & D&A (Owned PP&E + Intangibles) | E8: Capex & D&A Schedule (Rows 51-72): Tracks Owned PP&E and Intangible Assets (€12,778m at FY25A close, excluding IFRS 16 RoU assets). Depreciates existing net assets over E64 (10 yrs) and each new Capex vintage with half-year convention (E65 = 50%), linking total D&A directly to P&L Row 31.
C9: 5 | D9: =+LBO!D75 -> Debt Schedule (Senior TLA, Senior TLB & RCF with Cash Sweep) | E9: Multi-Tranche Debt & Cash Sweep Schedule (Rows 75-117): Models Senior TLA (1.5x EBITDA, E+2.75%, amortising 10/15/20/25/30%), Senior TLB (2.5x EBITDA, E+4.00%, 1% p.a. mandatory amortisation + 50% excess-cash sweep), and €3,000m RCF (auto-drawn if cash < minimum cash and repaid first).
C10: 6 | D10: =+LBO!D146 -> EBITDA reference (FY25A Pre-IFRS 16 Cash EBITDA) | E10: Free-Float Take-Private Perimeter & Sources & Uses (Rows 145-189): Acquires only the 35.65% free float at Offer Price = €55.42 * (1 + Premium %). The Ortega family (64.35%: Pontegadea 59.29% + Rosp Corunna 5.05%) rolls over 100% into Newco at the offer price. Excess cash above Minimum Cash (€3,000m) is deployed as a closing source.
C11: 7 | D11: =+LBO!D195 -> EBITDA Exit Multiple (Pre-IFRS 16) | E11: Exit Valuation, Returns (IRR / MoM) & Integrity Checks (Rows 192-232): Evaluates exit EV, net debt, and Sponsor/Family proceeds across FY26E-FY30E. Changing Exit Year (K149) dynamically updates headline IRR (F209) and MoM (F210). Includes a 3x3 sensitivity table (Premium x Leverage) and 6 automated integrity checks.

Sheet LBO
B1: Project Galicia — Inditex (ITX.MC)
A2: > | B2: LBO Model (Free-Float Take-Private & Family Rollover) | U2: Private & Confidential
A5: > | B5: > | C5: Operating model
B7: > | C7: Drivers | E7: 1 | F7: 2 | G7: 3 | H7: Active Case: | J7: 31-Jan | K7: 31-Jan | L7: 31-Jan | M7: 31-Jan | N7: 31-Jan | O7: 31-Jan | P7: 31-Jan | Q7: 31-Jan | R7: 31-Jan
D8: Operating Driver / Scenario Presets | E8: Base Case | F8: Bull Case | G8: Bear Case | H8: =CHOOSE($F$9,E8,F8,G8) -> Base Case | J8: 2022 | K8: =+J8+1 -> 2023 | L8: =+K8+1 -> 2024 | M8: =+L8+1 -> 2025 | N8: =+M8+1 -> 2026 | O8: =+N8+1 -> 2027 | P8: =+O8+1 -> 2028 | Q8: =+P8+1 -> 2029 | R8: =+Q8+1 -> 2030
B9: 1 | D9: Active Scenario Selector | F9: 1 | H9: =CHOOSE($F$9,E8,F8,G8) -> Base Case
D10: Revenue growth (% YoY) | E10: 0.055 | F10: 0.08 | G10: 0.0225 | H10: =CHOOSE($F$9,E10,F10,G10) -> 0.055 | J10: 0.175 | K10: 0.104 | L10: 0.075 | M10: 0.032 | N10: =+$H10 -> 0.055 | O10: =+$H10 -> 0.055 | P10: =+$H10 -> 0.055 | Q10: =+$H10 -> 0.055 | R10: =+$H10 -> 0.055
D11: Gross margin (% of revenues) | E11: 0.582 | F11: 0.59 | G11: 0.57 | H11: =CHOOSE($F$9,E11,F11,G11) -> 0.582 | J11: =+J23/J$21 -> 0.56983635 | K11: =+K23/K$21 -> 0.57757254 | L11: =+L23/L$21 -> 0.57835473 | M11: =+M23/M$21 -> 0.5825306 | N11: =+$H11 -> 0.582 | O11: =+$H11 -> 0.582 | P11: =+$H11 -> 0.582 | Q11: =+$H11 -> 0.582 | R11: =+$H11 -> 0.582
D12: OpEx growth (% YoY) | E12: 0.0425 | F12: 0.055 | G12: 0.0325 | H12: =CHOOSE($F$9,E12,F12,G12) -> 0.0425 | J12: 0.109 | K12: 0.1 | L12: 0.065 | M12: 0.028 | N12: =+$H12 -> 0.0425 | O12: =+$H12 -> 0.0425 | P12: =+$H12 -> 0.0425 | Q12: =+$H12 -> 0.0425 | R12: =+$H12 -> 0.0425
D13: Fixed lease cash outflow growth (%) | E13: 0.02 | F13: 0.03 | G13: 0.01 | H13: =CHOOSE($F$9,E13,F13,G13) -> 0.02 | J13: 0.05 | K13: =+K28/J28-1 -> 0.069093152 | L13: =+L28/K28-1 -> 0.039815349 | M13: =+M28/L28-1 -> 0.017758047 | N13: =+$H13 -> 0.02 | O13: =+$H13 -> 0.02 | P13: =+$H13 -> 0.02 | Q13: =+$H13 -> 0.02 | R13: =+$H13 -> 0.02
D14: Capex (% of revenues) | E14: 0.052 | F14: 0.0535 | G14: 0.049 | H14: =CHOOSE($F$9,E14,F14,G14) -> 0.052 | J14: =+J57/J$21 -> 0.043446222 | K14: =+K57/K$21 -> 0.052076668 | L14: =+L57/L$21 -> 0.069165459 | M14: =+M57/M$21 -> 0.068031306 | N14: =+$H14 -> 0.052 | O14: =+$H14 -> 0.052 | P14: =+$H14 -> 0.052 | Q14: =+$H14 -> 0.052 | R14: =+$H14 -> 0.052
D15: Inventory (% of revenues) | E15: 0.0815 | F15: 0.079 | G15: 0.085 | H15: =CHOOSE($F$9,E15,F15,G15) -> 0.0815 | J15: =+J43/J$21 -> 0.097976604 | K15: =+K43/K$21 -> 0.082510362 | L15: =+L43/L$21 -> 0.085965003 | M15: =+M43/M$21 -> 0.081502107 | N15: =+$H15 -> 0.0815 | O15: =+$H15 -> 0.0815 | P15: =+$H15 -> 0.0815 | Q15: =+$H15 -> 0.0815 | R15: =+$H15 -> 0.0815
D16: Receivables (% of revenues) | E16: 0.0292 | F16: 0.0285 | G16: 0.03 | H16: =CHOOSE($F$9,E16,F16,G16) -> 0.0292 | J16: =+J44/J$21 -> 0.026129141 | K16: =+K44/K$21 -> 0.028875845 | L16: =+L44/L$21 -> 0.028163181 | M16: =+M44/M$21 -> 0.029249448 | N16: =+$H16 -> 0.0292 | O16: =+$H16 -> 0.0292 | P16: =+$H16 -> 0.0292 | Q16: =+$H16 -> 0.0292 | R16: =+$H16 -> 0.0292
D17: Payables (% of revenues, negative) | E17: -0.2154 | F17: -0.2155 | G17: -0.213 | H17: =CHOOSE($F$9,E17,F17,G17) -> -0.2154 | J17: =+J45/J$21 -> -0.20144923 | K17: =+K45/K$21 -> -0.20772248 | L17: =+L45/L$21 -> -0.22235452 | M17: =+M45/M$21 -> -0.21540739 | N17: =+$H17 -> -0.2154 | O17: =+$H17 -> -0.2154 | P17: =+$H17 -> -0.2154 | Q17: =+$H17 -> -0.2154 | R17: =+$H17 -> -0.2154
B19: > | C19: P&L | J19: 31-Jan | K19: 31-Jan | L19: 31-Jan | M19: 31-Jan | N19: 31-Jan | O19: 31-Jan | P19: 31-Jan | Q19: 31-Jan | R19: 31-Jan | U19: CAGR 22A-25A | V19: CAGR 25A-30E
C20: €m | J20: 2022 | K20: =+J20+1 -> 2023 | L20: =+K20+1 -> 2024 | M20: =+L20+1 -> 2025 | N20: =+M20+1 -> 2026 | O20: =+N20+1 -> 2027 | P20: =+O20+1 -> 2028 | Q20: =+P20+1 -> 2029 | R20: =+Q20+1 -> 2030
B21: 2 | D21: Revenues | J21: 32569 | K21: 35947 | L21: 38632 | M21: 39864 | N21: =+M21*(1+N10) -> 42056.52 | O21: =+N21*(1+O10) -> 44369.629 | P21: =+O21*(1+P10) -> 46809.958 | Q21: =+P21*(1+Q10) -> 49384.506 | R21: =+Q21*(1+R10) -> 52100.654 | U21: =+IFERROR((M21/J21)^(1/(M$20-J$20))-1,0) -> 0.06969217 | V21: =+IFERROR((R21/M21)^(1/(R$20-M$20))-1,"n.a.") -> 0.055
D22: COGS | J22: =+J23-J21 -> -14010 | K22: =+K23-K21 -> -15185 | L22: =+L23-L21 -> -16289 | M22: =+M23-M21 -> -16642 | N22: =+N23-N21 -> -17579.625 | O22: =+O23-O21 -> -18546.505 | P22: =+P23-P21 -> -19566.563 | Q22: =+Q23-Q21 -> -20642.723 | R22: =+R23-R21 -> -21778.073 | U22: =+IFERROR((M22/J22)^(1/(M$20-J$20))-1,0) -> 0.059064622 | V22: =+IFERROR((R22/M22)^(1/(R$20-M$20))-1,"n.a.") -> 0.055268045
D23: Gross margin | J23: 18559 | K23: 20762 | L23: 22343 | M23: 23222 | N23: =+N21*N11 -> 24476.895 | O23: =+O21*O11 -> 25823.124 | P23: =+P21*P11 -> 27243.396 | Q23: =+Q21*Q11 -> 28741.782 | R23: =+R21*R11 -> 30322.58 | U23: =+IFERROR((M23/J23)^(1/(M$20-J$20))-1,0) -> 0.077577091 | V23: =+IFERROR((R23/M23)^(1/(R$20-M$20))-1,"n.a.") -> 0.054807738
D24: % margin | J24: =+IFERROR(J23/J$21,0) -> 0.56983635 | K24: =+IFERROR(K23/K$21,0) -> 0.57757254 | L24: =+IFERROR(L23/L$21,0) -> 0.57835473 | M24: =+IFERROR(M23/M$21,0) -> 0.5825306 | N24: =+IFERROR(N23/N$21,0) -> 0.582 | O24: =+IFERROR(O23/O$21,0) -> 0.582 | P24: =+IFERROR(P23/P$21,0) -> 0.582 | Q24: =+IFERROR(Q23/Q$21,0) -> 0.582 | R24: =+IFERROR(R23/R$21,0) -> 0.582 | U24: =+IFERROR((M24/J24)^(1/(M$20-J$20))-1,0) -> 0.0073712057 | V24: =+IFERROR((R24/M24)^(1/(R$20-M$20))-1,"n.a.") -> -0.00018223849
D25: Opex (incl. variable turnover rent) | J25: -9910 | K25: -10912 | L25: -11615 | M25: -11955 | N25: =+M25*(1+N12) -> -12463.087 | O25: =+N25*(1+O12) -> -12992.769 | P25: =+O25*(1+P12) -> -13544.961 | Q25: =+P25*(1+Q12) -> -14120.622 | R25: =+Q25*(1+R12) -> -14720.749 | U25: =+IFERROR((M25/J25)^(1/(M$20-J$20))-1,0) -> 0.064531806 | V25: =+IFERROR((R25/M25)^(1/(R$20-M$20))-1,"n.a.") -> 0.0425
D26: Reported EBITDA (Post-IFRS 16) | J26: =+J23+J25 -> 8649 | K26: =+K23+K25 -> 9850 | L26: =+L23+L25 -> 10728 | M26: =+M23+M25 -> 11267 | N26: =+N23+N25 -> 12013.807 | O26: =+O23+O25 -> 12830.355 | P26: =+P23+P25 -> 13698.434 | Q26: =+Q23+Q25 -> 14621.16 | R26: =+R23+R25 -> 15601.832 | U26: =+IFERROR((M26/J26)^(1/(M$20-J$20))-1,0) -> 0.09214625 | V26: =+IFERROR((R26/M26)^(1/(R$20-M$20))-1,"n.a.") -> 0.067267929
D27: % margin (Post-IFRS 16) | J27: =+IFERROR(J26/J$21,0) -> 0.26555927 | K27: =+IFERROR(K26/K$21,0) -> 0.27401452 | L27: =+IFERROR(L26/L$21,0) -> 0.27769725 | M27: =+IFERROR(M26/M$21,0) -> 0.28263596 | N27: =+IFERROR(N26/N$21,0) -> 0.28565861 | O27: =+IFERROR(O26/O$21,0) -> 0.28916977 | P27: =+IFERROR(P26/P$21,0) -> 0.29263932 | Q27: =+IFERROR(Q26/Q$21,0) -> 0.29606776 | R27: =+IFERROR(R26/R$21,0) -> 0.29945559 | U27: =+IFERROR((M27/J27)^(1/(M$20-J$20))-1,0) -> 0.020991161 | V27: =+IFERROR((R27/M27)^(1/(R$20-M$20))-1,"n.a.") -> 0.011628369
D28: Less: Fixed cash lease outflow (IFRS 16 adj.) | J28: -1621 | K28: -1733 | L28: -1802 | M28: -1834 | N28: =+M28*(1+N13) -> -1870.68 | O28: =+N28*(1+O13) -> -1908.0936 | P28: =+O28*(1+P13) -> -1946.2555 | Q28: =+P28*(1+Q13) -> -1985.1806 | R28: =+Q28*(1+R13) -> -2024.8842 | U28: =+IFERROR((M28/J28)^(1/(M$20-J$20))-1,0) -> 0.042010525 | V28: =+IFERROR((R28/M28)^(1/(R$20-M$20))-1,"n.a.") -> 0.02
D29: Pre-IFRS 16 Cash EBITDA (LBO Driver) | J29: =+J26+J28 -> 7028 | K29: =+K26+K28 -> 8117 | L29: =+L26+L28 -> 8926 | M29: =+M26+M28 -> 9433 | N29: =+N26+N28 -> 10143.127 | O29: =+O26+O28 -> 10922.262 | P29: =+P26+P28 -> 11752.179 | Q29: =+Q26+Q28 -> 12635.98 | R29: =+R26+R28 -> 13576.948 | U29: =+IFERROR((M29/J29)^(1/(M$20-J$20))-1,0) -> 0.1030775 | V29: =+IFERROR((R29/M29)^(1/(R$20-M$20))-1,"n.a.") -> 0.075549645
D30: % margin (Pre-IFRS 16) | J30: =+IFERROR(J29/J$21,0) -> 0.21578802 | K30: =+IFERROR(K29/K$21,0) -> 0.22580466 | L30: =+IFERROR(L29/L$21,0) -> 0.23105198 | M30: =+IFERROR(M29/M$21,0) -> 0.23662954 | N30: =+IFERROR(N29/N$21,0) -> 0.24117847 | O30: =+IFERROR(O29/O$21,0) -> 0.24616527 | P30: =+IFERROR(P29/P$21,0) -> 0.25106151 | Q30: =+IFERROR(Q29/Q$21,0) -> 0.25586931 | R30: =+IFERROR(R29/R$21,0) -> 0.26059073 | U30: =+IFERROR((M30/J30)^(1/(M$20-J$20))-1,0) -> 0.031210225 | V30: =+IFERROR((R30/M30)^(1/(R$20-M$20))-1,"n.a.") -> 0.019478336
D31: D&A (Owned PP&E & intangibles) | J31: =+J55 -> -1417 | K31: =+K55 -> -1558 | L31: =+L55 -> -1638 | M31: =+M55 -> -1674 | N31: =+N55 -> -1387.147 | O31: =+O55 -> -1611.8549 | P31: =+P55 -> -1848.9219 | Q31: =+Q55 -> -2099.0275 | R31: =+R55 -> -2362.8889 | U31: =+IFERROR((M31/J31)^(1/(M$20-J$20))-1,0) -> 0.057130333 | V31: =+IFERROR((R31/M31)^(1/(R$20-M$20))-1,"n.a.") -> 0.071365283
D32: Adj. EBIT (Pre-IFRS 16) | J32: =+J29+J31 -> 5611 | K32: =+K29+K31 -> 6559 | L32: =+L29+L31 -> 7288 | M32: =+M29+M31 -> 7759 | N32: =+N29+N31 -> 8755.9802 | O32: =+O29+O31 -> 9310.4066 | P32: =+P29+P31 -> 9903.2569 | Q32: =+Q29+Q31 -> 10536.952 | R32: =+R29+R31 -> 11214.059 | U32: =+IFERROR((M32/J32)^(1/(M$20-J$20))-1,0) -> 0.11409398 | V32: =+IFERROR((R32/M32)^(1/(R$20-M$20))-1,"n.a.") -> 0.076443933
D33: Interests (LBO debt & RCF fees) | F33: =+F160 -> 0.0653125 | J33: -69 | K33: 61 | L33: 23 | M33: 23 | N33: =+N116 -> -2425.9376 | O33: =+O116 -> -2213.4801 | P33: =+P116 -> -1913.1155 | Q33: =+Q116 -> -1544.6372 | R33: =+R116 -> -1114.745
D34: EBT | J34: =+SUM(J32:J33) -> 5542 | K34: =+SUM(K32:K33) -> 6620 | L34: =+SUM(L32:L33) -> 7311 | M34: =+SUM(M32:M33) -> 7782 | N34: =+SUM(N32:N33) -> 6330.0426 | O34: =+SUM(O32:O33) -> 7096.9265 | P34: =+SUM(P32:P33) -> 7990.1414 | Q34: =+SUM(Q32:Q33) -> 8992.3149 | R34: =+SUM(R32:R33) -> 10099.314 | U34: =+IFERROR((M34/J34)^(1/(M$20-J$20))-1,0) -> 0.11980285 | V34: =+IFERROR((R34/M34)^(1/(R$20-M$20))-1,"n.a.") -> 0.053513553
D35: Tax | F35: 0.224 | J35: -1211 | K35: -1475 | L35: -1700 | M35: -1800 | N35: =+IF(N34>0,-N34*$F$35,0) -> -1417.9295 | O35: =+IF(O34>0,-O34*$F$35,0) -> -1589.7115 | P35: =+IF(P34>0,-P34*$F$35,0) -> -1789.7917 | Q35: =+IF(Q34>0,-Q34*$F$35,0) -> -2014.2785 | R35: =+IF(R34>0,-R34*$F$35,0) -> -2262.2463 | U35: =+IFERROR((M35/J35)^(1/(M$20-J$20))-1,0) -> 0.14123773 | V35: =+IFERROR((R35/M35)^(1/(R$20-M$20))-1,"n.a.") -> 0.046775321
D36: Net income | J36: =+SUM(J34:J35) -> 4331 | K36: =+SUM(K34:K35) -> 5145 | L36: =+SUM(L34:L35) -> 5611 | M36: =+SUM(M34:M35) -> 5982 | N36: =+SUM(N34:N35) -> 4912.1131 | O36: =+SUM(O34:O35) -> 5507.215 | P36: =+SUM(P34:P35) -> 6200.3498 | Q36: =+SUM(Q34:Q35) -> 6978.0363 | R36: =+SUM(R34:R35) -> 7837.0674 | U36: =+IFERROR((M36/J36)^(1/(M$20-J$20))-1,0) -> 0.11366031 | V36: =+IFERROR((R36/M36)^(1/(R$20-M$20))-1,"n.a.") -> 0.05550777
B39: > | C39: BS | J39: 31-Jan | K39: 31-Jan | L39: 31-Jan | M39: 31-Jan | N39: 31-Jan | O39: 31-Jan | P39: 31-Jan | Q39: 31-Jan | R39: 31-Jan
C40: €m | J40: =+J20 -> 2022 | K40: =+J40+1 -> 2023 | L40: =+K40+1 -> 2024 | M40: =+L40+1 -> 2025 | N40: =+M40+1 -> 2026 | O40: =+N40+1 -> 2027 | P40: =+O40+1 -> 2028 | Q40: =+P40+1 -> 2029 | R40: =+Q40+1 -> 2030
B42: 3 | C42: > | D42: WK (Operating Working Capital)
D43: Inventory | J43: 3191 | K43: 2966 | L43: 3321 | M43: 3249 | N43: =+N$21*N15 -> 3427.6064 | O43: =+O$21*O15 -> 3616.1247 | P43: =+P$21*P15 -> 3815.0116 | Q43: =+Q$21*Q15 -> 4024.8372 | R43: =+R$21*R15 -> 4246.2033
D44: Receivables | J44: 851 | K44: 1038 | L44: 1088 | M44: 1166 | N44: =+N$21*N16 -> 1228.0504 | O44: =+O$21*O16 -> 1295.5932 | P44: =+P$21*P16 -> 1366.8508 | Q44: =+Q$21*Q16 -> 1442.0276 | R44: =+R$21*R16 -> 1521.3391
D45: Payables | J45: -6561 | K45: -7467 | L45: -8590 | M45: -8587 | N45: =+N$21*N17 -> -9058.9744 | O45: =+O$21*O17 -> -9557.218 | P45: =+P$21*P17 -> -10082.865 | Q45: =+Q$21*Q17 -> -10637.423 | R45: =+R$21*R17 -> -11222.481
D46: Total WK (EoP balance) | J46: =+SUM(J43:J45) -> -2519 | K46: =+SUM(K43:K45) -> -3463 | L46: =+SUM(L43:L45) -> -4181 | M46: =+SUM(M43:M45) -> -4172 | N46: =+SUM(N43:N45) -> -4403.3176 | O46: =+SUM(O43:O45) -> -4645.5001 | P46: =+SUM(P43:P45) -> -4901.0026 | Q46: =+SUM(Q43:Q45) -> -5170.5578 | R46: =+SUM(R43:R45) -> -5454.9384
D47: WK % of revenues | J47: =+IFERROR(J46/J$21,0) -> -0.077343486 | K47: =+IFERROR(K46/K$21,0) -> -0.096336273 | L47: =+IFERROR(L46/L$21,0) -> -0.10822634 | M47: =+IFERROR(M46/M$21,0) -> -0.10465583 | N47: =+IFERROR(N46/N$21,0) -> -0.1047 | O47: =+IFERROR(O46/O$21,0) -> -0.1047 | P47: =+IFERROR(P46/P$21,0) -> -0.1047 | Q47: =+IFERROR(Q46/Q$21,0) -> -0.1047 | R47: =+IFERROR(R46/R$21,0) -> -0.1047
...
